Workbook

Sheet 订单模型
A1: 类型 | B1: 数量 | C1: 分项 | D1: 1 | E1: 2 | F1: 3 | G1: 4 | H1: 5 | I1: 6 | J1: 7 | K1: 8 | L1: 9 | M1: 10 | N1: 11 | O1: 12 | P1: 13 | Q1: 14 | R1: 控制参数
A2: 贸易 项目 | B2: 3 | C2: 总额 | D2: 13 | E2: =D2 -> 13 | F2: =D2+1 -> 14 | G2: =D2+1 -> 14 | H2: =D2+2 -> 15 | I2: =D2+2 -> 15 | J2: =D2+3 -> 16 | K2: =D2+3 -> 16 | L2: =H2+2 -> 17 | M2: =H2+2 -> 17 | N2: =J2+2 -> 18 | O2: =J2+2 -> 18 | P2: =L2+2 -> 19 | Q2: =L2+2 -> 19 | R2: 4
C3: 单价 | D3: =FIXED(D2/$B2,2,TRUE) -> 4.33 | E3: =FIXED(E2/$B2,2,TRUE) -> 4.33 | F3: =FIXED(F2/$B2,2,TRUE) -> 4.67 | G3: =FIXED(G2/$B2,2,TRUE) -> 4.67 | H3: =FIXED(H2/$B2,2,TRUE) -> 5.00 | I3: =FIXED(I2/$B2,2,TRUE) -> 5.00 | J3: =FIXED(J2/$B2,2,TRUE) -> 5.33 | K3: =FIXED(K2/$B2,2,TRUE) -> 5.33 | ... Q3: =FIXED(Q2/$B2,2,TRUE) -> 6.33
B4: 4 | C4: 总额 | D4: =D2+R2 -> 17 | E4: =D4 -> 17 | F4: =D4+1 -> 18 | G4: =D4+1 -> 18 | H4: =F4+1 -> 19 | I4: =F4+1 -> 19 | J4: =H4+1 -> 20 | K4: =H4+1 -> 20 | L4: =J4+1 -> 21 | M4: =J4+1 -> 21 | N4: =L4+1 -> 22 | O4: =L4+1 -> 22 | P4: =N4+1 -> 23 | Q4: =N4+1 -> 23
C5: 单价 | D5: =FIXED(D4/$B4,2,TRUE) -> 4.25 | E5: =FIXED(E4/$B4,2,TRUE) -> 4.25 | F5: =FIXED(F4/$B4,2,TRUE) -> 4.50 | G5: =FIXED(G4/$B4,2,TRUE) -> 4.50 | H5: =FIXED(H4/$B4,2,TRUE) -> 4.75 | I5: =FIXED(I4/$B4,2,TRUE) -> 4.75 | J5: =FIXED(J4/$B4,2,TRUE) -> 5.00 | K5: =FIXED(K4/$B4,2,TRUE) -> 5.00 | ... Q5: =FIXED(Q4/$B4,2,TRUE) -> 5.75
B6: 5 | C6: 总额 | D6: =D4+$R2 -> 21 | E6: =E4+$R2 -> 21 | F6: =F4+$R2 -> 22 | G6: =G4+$R2 -> 22 | H6: =H4+$R2 -> 23 | I6: =I4+$R2 -> 23 | J6: =J4+$R2 -> 24 | K6: =K4+$R2 -> 24 | ... Q6: =Q4+$R2 -> 27
C7: 单价 | D7: =FIXED(D6/$B6,2,TRUE) -> 4.20 | E7: =FIXED(E6/$B6,2,TRUE) -> 4.20 | F7: =FIXED(F6/$B6,2,TRUE) -> 4.40 | G7: =FIXED(G6/$B6,2,TRUE) -> 4.40 | H7: =FIXED(H6/$B6,2,TRUE) -> 4.60 | I7: =FIXED(I6/$B6,2,TRUE) -> 4.60 | J7: =FIXED(J6/$B6,2,TRUE) -> 4.80 | K7: =FIXED(K6/$B6,2,TRUE) -> 4.80 | ... Q7: =FIXED(Q6/$B6,2,TRUE) -> 5.40
B8: 6 | C8: 总额 | D8: =D6+$R2 -> 25 | E8: =E6+$R2 -> 25 | F8: =F6+$R2 -> 26 | G8: =G6+$R2 -> 26 | H8: =H6+$R2 -> 27 | I8: =I6+$R2 -> 27 | J8: =J6+$R2 -> 28 | K8: =K6+$R2 -> 28 | ... Q8: =Q6+$R2 -> 31
C9: 单价 | D9: =FIXED(D8/$B8,2,TRUE) -> 4.17 | E9: =FIXED(E8/$B8,2,TRUE) -> 4.17 | F9: =FIXED(F8/$B8,2,TRUE) -> 4.33 | G9: =FIXED(G8/$B8,2,TRUE) -> 4.33 | H9: =FIXED(H8/$B8,2,TRUE) -> 4.50 | I9: =FIXED(I8/$B8,2,TRUE) -> 4.50 | J9: =FIXED(J8/$B8,2,TRUE) -> 4.67 | K9: =FIXED(K8/$B8,2,TRUE) -> 4.67 | ... Q9: =FIXED(Q8/$B8,2,TRUE) -> 5.17
B10: 7 | C10: 总额 | D10: =D8+$R2 -> 29 | E10: =E8+$R2 -> 29 | F10: =F8+$R2 -> 30 | G10: =G8+$R2 -> 30 | H10: =H8+$R2 -> 31 | I10: =I8+$R2 -> 31 | J10: =J8+$R2 -> 32 | K10: =K8+$R2 -> 32 | ... Q10: =Q8+$R2 -> 35
C11: 单价 | D11: =FIXED(D10/$B10,2,TRUE) -> 4.14 | E11: =FIXED(E10/$B10,2,TRUE) -> 4.14 | F11: =FIXED(F10/$B10,2,TRUE) -> 4.29 | G11: =FIXED(G10/$B10,2,TRUE) -> 4.29 | H11: =FIXED(H10/$B10,2,TRUE) -> 4.43 | I11: =FIXED(I10/$B10,2,TRUE) -> 4.43 | J11: =FIXED(J10/$B10,2,TRUE) -> 4.57 | K11: =FIXED(K10/$B10,2,TRUE) -> 4.57 | ... Q11: =FIXED(Q10/$B10,2,TRUE) -> 5.00
A12: 集成 项目 | B12: 2 | C12: 总额 | D12: 12 | E12: =D12 -> 12 | F12: =D12+1 -> 13 | G12: =D12+1 -> 13 | H12: =F12+1 -> 14 | I12: =F12+1 -> 14 | J12: =H12+1 -> 15 | K12: =H12+1 -> 15 | L12: =J12+1 -> 16 | M12: =J12+1 -> 16 | N12: =L12+1 -> 17 | O12: =L12+1 -> 17 | P12: =N12+1 -> 18 | Q12: =N12+1 -> 18 | R12: 6
C13: 单价 | D13: =FIXED(D12/$B12,2,TRUE) -> 6.00 | E13: =FIXED(E12/$B12,2,TRUE) -> 6.00 | F13: =FIXED(F12/$B12,2,TRUE) -> 6.50 | G13: =FIXED(G12/$B12,2,TRUE) -> 6.50 | H13: =FIXED(H12/$B12,2,TRUE) -> 7.00 | I13: =FIXED(I12/$B12,2,TRUE) -> 7.00 | J13: =FIXED(J12/$B12,2,TRUE) -> 7.50 | K13: =FIXED(K12/$B12,2,TRUE) -> 7.50 | ... Q13: =FIXED(Q12/$B12,2,TRUE) -> 9.00
B14: 3 | C14: 总额 | D14: =D12+$R12 -> 18 | E14: =E12+$R12 -> 18 | F14: =F12+$R12 -> 19 | G14: =G12+$R12 -> 19 | H14: =H12+$R12 -> 20 | I14: =I12+$R12 -> 20 | J14: =J12+$R12 -> 21 | K14: =K12+$R12 -> 21 | ... Q14: =Q12+$R12 -> 24
C15: 单价 | D15: =FIXED(D14/$B14,2,TRUE) -> 6.00 | E15: =FIXED(E14/$B14,2,TRUE) -> 6.00 | F15: =FIXED(F14/$B14,2,TRUE) -> 6.33 | G15: =FIXED(G14/$B14,2,TRUE) -> 6.33 | H15: =FIXED(H14/$B14,2,TRUE) -> 6.67 | I15: =FIXED(I14/$B14,2,TRUE) -> 6.67 | J15: =FIXED(J14/$B14,2,TRUE) -> 7.00 | K15: =FIXED(K14/$B14,2,TRUE) -> 7.00 | ... Q15: =FIXED(Q14/$B14,2,TRUE) -> 8.00
B16: 4 | C16: 总额 | D16: =D14+$R12 -> 24 | E16: =E14+$R12 -> 24 | F16: =F14+$R12 -> 25 | G16: =G14+$R12 -> 25 | H16: =H14+$R12 -> 26 | I16: =I14+$R12 -> 26 | J16: =J14+$R12 -> 27 | K16: =K14+$R12 -> 27 | ... Q16: =Q14+$R12 -> 30
C17: 单价 | D17: =FIXED(D16/$B16,2,TRUE) -> 6.00 | E17: =FIXED(E16/$B16,2,TRUE) -> 6.00 | F17: =FIXED(F16/$B16,2,TRUE) -> 6.25 | G17: =FIXED(G16/$B16,2,TRUE) -> 6.25 | H17: =FIXED(H16/$B16,2,TRUE) -> 6.50 | I17: =FIXED(I16/$B16,2,TRUE) -> 6.50 | J17: =FIXED(J16/$B16,2,TRUE) -> 6.75 | K17: =FIXED(K16/$B16,2,TRUE) -> 6.75 | ... Q17: =FIXED(Q16/$B16,2,TRUE) -> 7.50
B18: 5 | C18: 总额 | D18: =D16+$R12 -> 30 | E18: =E16+$R12 -> 30 | F18: =F16+$R12 -> 31 | G18: =G16+$R12 -> 31 | H18: =H16+$R12 -> 32 | I18: =I16+$R12 -> 32 | J18: =J16+$R12 -> 33 | K18: =K16+$R12 -> 33 | ... Q18: =Q16+$R12 -> 36
C19: 单价 | D19: =FIXED(D18/$B18,2,TRUE) -> 6.00 | E19: =FIXED(E18/$B18,2,TRUE) -> 6.00 | F19: =FIXED(F18/$B18,2,TRUE) -> 6.20 | G19: =FIXED(G18/$B18,2,TRUE) -> 6.20 | H19: =FIXED(H18/$B18,2,TRUE) -> 6.40 | I19: =FIXED(I18/$B18,2,TRUE) -> 6.40 | J19: =FIXED(J18/$B18,2,TRUE) -> 6.60 | K19: =FIXED(K18/$B18,2,TRUE) -> 6.60 | ... Q19: =FIXED(Q18/$B18,2,TRUE) -> 7.20
B20: 6 | C20: 总额 | D20: =D18+$R12 -> 36 | E20: =E18+$R12 -> 36 | F20: =F18+$R12 -> 37 | G20: =G18+$R12 -> 37 | H20: =H18+$R12 -> 38 | I20: =I18+$R12 -> 38 | J20: =J18+$R12 -> 39 | K20: =K18+$R12 -> 39 | ... Q20: =Q18+$R12 -> 42
C21: 单价 | D21: =FIXED(D20/$B20,2,TRUE) -> 6.00 | E21: =FIXED(E20/$B20,2,TRUE) -> 6.00 | F21: =FIXED(F20/$B20,2,TRUE) -> 6.17 | G21: =FIXED(G20/$B20,2,TRUE) -> 6.17 | H21: =FIXED(H20/$B20,2,TRUE) -> 6.33 | I21: =FIXED(I20/$B20,2,TRUE) -> 6.33 | J21: =FIXED(J20/$B20,2,TRUE) -> 6.50 | K21: =FIXED(K20/$B20,2,TRUE) -> 6.50 | ... Q21: =FIXED(Q20/$B20,2,TRUE) -> 7.00
A22: 服务 项目 | B22: 1 | C22: 总额 | D22: 9 | E22: =D22 -> 9 | F22: =D22+1 -> 10 | G22: =F22 -> 10 | H22: 10 | I22: =H22 -> 10 | J22: =H22+1 -> 11 | K22: =J22 -> 11 | L22: 11 | M22: =L22 -> 11 | N22: =L22+1 -> 12 | O22: =N22 -> 12 | P22: 12 | Q22: =P22 -> 12 | R22: 8
C23: 单价 | D23: =FIXED(D22/$B22,2,TRUE) -> 9.00 | E23: =FIXED(E22/$B22,2,TRUE) -> 9.00 | F23: =FIXED(F22/$B22,2,TRUE) -> 10.00 | G23: =FIXED(G22/$B22,2,TRUE) -> 10.00 | H23: =FIXED(H22/$B22,2,TRUE) -> 10.00 | I23: =FIXED(I22/$B22,2,TRUE) -> 10.00 | J23: =FIXED(J22/$B22,2,TRUE) -> 11.00 | K23: =FIXED(K22/$B22,2,TRUE) -> 11.00 | ... Q23: =FIXED(Q22/$B22,2,TRUE) -> 12.00
B24: 2 | C24: 总额 | D24: =D22+$R22 -> 17 | E24: =D24 -> 17 | F24: =E24+1 -> 18 | G24: =D24+1 -> 18 | H24: =G24+1 -> 19 | I24: =F24+1 -> 19 | J24: =H24+1 -> 20 | K24: =H24+1 -> 20 | L24: =J24+1 -> 21 | M24: =J24+1 -> 21 | N24: =L24+1 -> 22 | O24: =L24+1 -> 22 | P24: =N24+1 -> 23 | Q24: =N24+1 -> 23
C25: 单价 | D25: =FIXED(D24/$B24,2,TRUE) -> 8.50 | E25: =FIXED(E24/$B24,2,TRUE) -> 8.50 | F25: =FIXED(F24/$B24,2,TRUE) -> 9.00 | G25: =FIXED(G24/$B24,2,TRUE) -> 9.00 | H25: =FIXED(H24/$B24,2,TRUE) -> 9.50 | I25: =FIXED(I24/$B24,2,TRUE) -> 9.50 | J25: =FIXED(J24/$B24,2,TRUE) -> 10.00 | K25: =FIXED(K24/$B24,2,TRUE) -> 10.00 | ... Q25: =FIXED(Q24/$B24,2,TRUE) -> 11.50
B26: 3 | C26: 总额 | D26: =D24+$R22 -> 25 | E26: =E24+$R22 -> 25 | F26: =F24+$R22 -> 26 | G26: =G24+$R22 -> 26 | H26: =H24+$R22 -> 27 | I26: =I24+$R22 -> 27 | J26: =J24+$R22 -> 28 | K26: =K24+$R22 -> 28 | ... Q26: =Q24+$R22 -> 31
C27: 单价 | D27: =FIXED(D26/$B26,2,TRUE) -> 8.33 | E27: =FIXED(E26/$B26,2,TRUE) -> 8.33 | F27: =FIXED(F26/$B26,2,TRUE) -> 8.67 | G27: =FIXED(G26/$B26,2,TRUE) -> 8.67 | H27: =FIXED(H26/$B26,2,TRUE) -> 9.00 | I27: =FIXED(I26/$B26,2,TRUE) -> 9.00 | J27: =FIXED(J26/$B26,2,TRUE) -> 9.33 | K27: =FIXED(K26/$B26,2,TRUE) -> 9.33 | ... Q27: =FIXED(Q26/$B26,2,TRUE) -> 10.33
B28: 4 | C28: 总额 | D28: =D26+$R22 -> 33 | E28: =E26+$R22 -> 33 | F28: =F26+$R22 -> 34 | G28: =G26+$R22 -> 34 | H28: =H26+$R22 -> 35 | I28: =I26+$R22 -> 35 | J28: =J26+$R22 -> 36 | K28: =K26+$R22 -> 36 | ... Q28: =Q26+$R22 -> 39
C29: 单价 | D29: =FIXED(D28/$B28,2,TRUE) -> 8.25 | E29: =FIXED(E28/$B28,2,TRUE) -> 8.25 | F29: =FIXED(F28/$B28,2,TRUE) -> 8.50 | G29: =FIXED(G28/$B28,2,TRUE) -> 8.50 | H29: =FIXED(H28/$B28,2,TRUE) -> 8.75 | I29: =FIXED(I28/$B28,2,TRUE) -> 8.75 | J29: =FIXED(J28/$B28,2,TRUE) -> 9.00 | K29: =FIXED(K28/$B28,2,TRUE) -> 9.00 | ... Q29: =FIXED(Q28/$B28,2,TRUE) -> 9.75
B30: 5 | C30: 总额 | D30: =D28+$R22 -> 41 | E30: =E28+$R22 -> 41 | F30: =F28+$R22 -> 42 | G30: =G28+$R22 -> 42 | H30: =H28+$R22 -> 43 | I30: =I28+$R22 -> 43 | J30: =J28+$R22 -> 44 | K30: =K28+$R22 -> 44 | ... Q30: =Q28+$R22 -> 47
C31: 单价 | D31: =FIXED(D30/$B30,2,TRUE) -> 8.20 | E31: =FIXED(E30/$B30,2,TRUE) -> 8.20 | F31: =FIXED(F30/$B30,2,TRUE) -> 8.40 | G31: =FIXED(G30/$B30,2,TRUE) -> 8.40 | H31: =FIXED(H30/$B30,2,TRUE) -> 8.60 | I31: =FIXED(I30/$B30,2,TRUE) -> 8.60 | J31: =FIXED(J30/$B30,2,TRUE) -> 8.80 | K31: =FIXED(K30/$B30,2,TRUE) -> 8.80 | ... Q31: =FIXED(Q30/$B30,2,TRUE) -> 9.40
A32: 科创 项目 | B32: 1 | C32: 总额 | D32: 11 | E32: =D32 -> 11 | F32: =E32+1 -> 12 | G32: =F32 -> 12 | H32: 12 | I32: =H32 -> 12 | J32: =I32+1 -> 13 | K32: =J32 -> 13 | L32: 13 | M32: =L32 -> 13 | N32: =M32+1 -> 14 | O32: =N32 -> 14 | P32: 14 | Q32: =P32 -> 14 | R32: 10
C33: 单价 | D33: =FIXED(D32/$B32,2,TRUE) -> 11.00 | E33: =FIXED(E32/$B32,2,TRUE) -> 11.00 | F33: =FIXED(F32/$B32,2,TRUE) -> 12.00 | G33: =FIXED(G32/$B32,2,TRUE) -> 12.00 | H33: =FIXED(H32/$B32,2,TRUE) -> 12.00 | I33: =FIXED(I32/$B32,2,TRUE) -> 12.00 | J33: =FIXED(J32/$B32,2,TRUE) -> 13.00 | K33: =FIXED(K32/$B32,2,TRUE) -> 13.00 | ... Q33: =FIXED(Q32/$B32,2,TRUE) -> 14.00
B34: 2 | C34: 总额 | D34: =D32+$R32 -> 21 | E34: =E32+$R32 -> 21 | F34: =D34+1 -> 22 | G34: =D34+1 -> 22 | H34: =F34+1 -> 23 | I34: =H34 -> 23 | J34: =H34+1 -> 24 | K34: =H34+1 -> 24 | L34: =J34+1 -> 25 | M34: =K34+1 -> 25 | N34: =L34+1 -> 26 | O34: =M34+1 -> 26 | P34: =N34+1 -> 27 | Q34: =O34+1 -> 27
C35: 单价 | D35: =FIXED(D34/$B34,2,TRUE) -> 10.50 | E35: =FIXED(E34/$B34,2,TRUE) -> 10.50 | F35: =FIXED(F34/$B34,2,TRUE) -> 11.00 | G35: =FIXED(G34/$B34,2,TRUE) -> 11.00 | H35: =FIXED(H34/$B34,2,TRUE) -> 11.50 | I35: =FIXED(I34/$B34,2,TRUE) -> 11.50 | J35: =FIXED(J34/$B34,2,TRUE) -> 12.00 | K35: =FIXED(K34/$B34,2,TRUE) -> 12.00 | ... Q35: =FIXED(Q34/$B34,2,TRUE) -> 13.50
B36: 3 | C36: 总额 | D36: =D34+$R32 -> 31 | E36: =E34+$R32 -> 31 | F36: =F34+$R32 -> 32 | G36: =G34+$R32 -> 32 | H36: =H34+$R32 -> 33 | I36: =I34+$R32 -> 33 | J36: =J34+$R32 -> 34 | K36: =K34+$R32 -> 34 | ... Q36: =Q34+$R32 -> 37
C37: 单价 | D37: =FIXED(D36/$B36,2,TRUE) -> 10.33 | E37: =FIXED(E36/$B36,2,TRUE) -> 10.33 | F37: =FIXED(F36/$B36,2,TRUE) -> 10.67 | G37: =FIXED(G36/$B36,2,TRUE) -> 10.67 | H37: =FIXED(H36/$B36,2,TRUE) -> 11.00 | I37: =FIXED(I36/$B36,2,TRUE) -> 11.00 | J37: =FIXED(J36/$B36,2,TRUE) -> 11.33 | K37: =FIXED(K36/$B36,2,TRUE) -> 11.33 | ... Q37: =FIXED(Q36/$B36,2,TRUE) -> 12.33
B38: 4 | C38: 总额 | D38: =D36+$R32 -> 41 | E38: =E36+$R32 -> 41 | F38: =F36+$R32 -> 42 | G38: =G36+$R32 -> 42 | H38: =H36+$R32 -> 43 | I38: =I36+$R32 -> 43 | J38: =J36+$R32 -> 44 | K38: =K36+$R32 -> 44 | ... Q38: =Q36+$R32 -> 47
C39: 单价 | D39: =FIXED(D38/$B38,2,TRUE) -> 10.25 | E39: =FIXED(E38/$B38,2,TRUE) -> 10.25 | F39: =FIXED(F38/$B38,2,TRUE) -> 10.50 | G39: =FIXED(G38/$B38,2,TRUE) -> 10.50 | H39: =FIXED(H38/$B38,2,TRUE) -> 10.75 | I39: =FIXED(I38/$B38,2,TRUE) -> 10.75 | J39: =FIXED(J38/$B38,2,TRUE) -> 11.00 | K39: =FIXED(K38/$B38,2,TRUE) -> 11.00 | ... Q39: =FIXED(Q38/$B38,2,TRUE) -> 11.75
C40: 价格因素 | D40: 严重过剩 | E40: 严重过剩 | F40: 供大于求 | G40: 供大于求 | H40: 供略大于求 | I40: 供略大于求 | J40: 供求平衡 | K40: 供求平衡 | L40: 需求较大 | M40: 需求较大 | N40: 需求旺盛 | O40: 需求旺盛 | P40: 供不应求 | Q40: 供不应求
...

Sheet 数量推算
A2: 公司数 | B2: 5
A3: 类别 | B3: 贸易项目 | C3: 集成项目 | D3: 服务项目 | E3: 科创项目
A4: 本地市场 | B4: 5 | C4: 4 | D4: 0.5 | E4: 0.2
A5: 全国市场 | B5: 4 | C5: 4 | D5: 1 | E5: 0.5
A6: 亚太市场 | B6: 2 | C6: 2 | D6: 1 | E6: 1
A7: 全球市场 | B7: 0 | C7: 2 | D7: 1 | E7: 1

Sheet 市场地位（横）
A1: 第一年
A2: 区域 | B2: 本地 | D2: 全国 | F2: 亚太 | H2: 全球 | J2: 总计 | L2: 贸易 | N2: 集成 | P2: 服务 | R2: 科创
A3: 类别 | B3: 地位 | C3: 份额 | D3: 地位 | E3: 份额 | F3: 地位 | G3: 份额 | H3: 地位 | I3: 份额 | J3: 占比 | K3: 份额 | L3: 地位 | M3: 份额 | N3: 地位 | O3: 份额 | P3: 地位 | Q3: 份额 | R3: 地位 | S3: 份额
A4: 1组 | B4: =#REF! -> #REF! | C4: =#REF!+#REF!+#REF!+#REF! -> #REF! | D4: =#REF! -> #REF! | E4: =#REF!+#REF!+#REF!+#REF! -> #REF! | F4: =#REF! -> #REF! | G4: =#REF!+#REF!+#REF!+#REF! -> #REF! | H4: =#REF! -> #REF! | I4: =#REF!+#REF!+#REF!+#REF! -> #REF! | J4: =K4/SUM($K$4:$K$18) -> #REF! | K4: =C4+E4+G4+I4 -> #REF! | M4: =#REF!+#REF!+#REF!+#REF! -> #REF! | O4: =#REF!+#REF!+#REF!+#REF! -> #REF! | Q4: =#REF!+#REF!+#REF!+#REF! -> #REF! | S4: =#REF!+#REF!+#REF!+#REF! -> #REF! | X4: 第一年市占比
A5: 2组 | B5: =#REF! -> #REF! | C5: =#REF!+#REF!+#REF!+#REF! -> #REF! | D5: =#REF! -> #REF! | E5: =#REF!+#REF!+#REF!+#REF! -> #REF! | F5: =#REF! -> #REF! | G5: =#REF!+#REF!+#REF!+#REF! -> #REF! | H5: =#REF! -> #REF! | I5: =#REF!+#REF!+#REF!+#REF! -> #REF! | J5: =K5/SUM($K$4:$K$18) -> #REF! | K5: =C5+E5+G5+I5 -> #REF! | M5: =#REF!+#REF!+#REF!+#REF! -> #REF! | O5: =#REF!+#REF!+#REF!+#REF! -> #REF! | Q5: =#REF!+#REF!+#REF!+#REF! -> #REF! | S5: =#REF!+#REF!+#REF!+#REF! -> #REF!
A6: 3组 | B6: =#REF! -> #REF! | C6: =#REF!+#REF!+#REF!+#REF! -> #REF! | D6: =#REF! -> #REF! | E6: =#REF!+#REF!+#REF!+#REF! -> #REF! | F6: =#REF! -> #REF! | G6: =#REF!+#REF!+#REF!+#REF! -> #REF! | H6: =#REF! -> #REF! | I6: =#REF!+#REF!+#REF!+#REF! -> #REF! | J6: =K6/SUM($K$4:$K$18) -> #REF! | K6: =C6+E6+G6+I6 -> #REF! | M6: =#REF!+#REF!+#REF!+#REF! -> #REF! | O6: =#REF!+#REF!+#REF!+#REF! -> #REF! | Q6: =#REF!+#REF!+#REF!+#REF! -> #REF! | S6: =#REF!+#REF!+#REF!+#REF! -> #REF!
A7: 4组 | B7: =#REF! -> #REF! | C7: =#REF!+#REF!+#REF!+#REF! -> #REF! | D7: =#REF! -> #REF! | E7: =#REF!+#REF!+#REF!+#REF! -> #REF! | F7: =#REF! -> #REF! | G7: =#REF!+#REF!+#REF!+#REF! -> #REF! | H7: =#REF! -> #REF! | I7: =#REF!+#REF!+#REF!+#REF! -> #REF! | J7: =K7/SUM($K$4:$K$18) -> #REF! | K7: =C7+E7+G7+I7 -> #REF! | M7: =#REF!+#REF!+#REF!+#REF! -> #REF! | O7: =#REF!+#REF!+#REF!+#REF! -> #REF! | Q7: =#REF!+#REF!+#REF!+#REF! -> #REF! | S7: =#REF!+#REF!+#REF!+#REF! -> #REF!
A8: 5组 | B8: =#REF! -> #REF! | C8: =#REF!+#REF!+#REF!+#REF! -> #REF! | D8: =#REF! -> #REF! | E8: =#REF!+#REF!+#REF!+#REF! -> #REF! | F8: =#REF! -> #REF! | G8: =#REF!+#REF!+#REF!+#REF! -> #REF! | H8: =#REF! -> #REF! | I8: =#REF!+#REF!+#REF!+#REF! -> #REF! | J8: =K8/SUM($K$4:$K$18) -> #REF! | K8: =C8+E8+G8+I8 -> #REF! | M8: =#REF!+#REF!+#REF!+#REF! -> #REF! | O8: =#REF!+#REF!+#REF!+#REF! -> #REF! | Q8: =#REF!+#REF!+#REF!+#REF! -> #REF! | S8: =#REF!+#REF!+#REF!+#REF! -> #REF!
A9: 6组 | B9: =#REF! -> #REF! | C9: =#REF!+#REF!+#REF!+#REF! -> #REF! | D9: =#REF! -> #REF! | E9: =#REF!+#REF!+#REF!+#REF! -> #REF! | F9: =#REF! -> #REF! | G9: =#REF!+#REF!+#REF!+#REF! -> #REF! | H9: =#REF! -> #REF! | I9: =#REF!+#REF!+#REF!+#REF! -> #REF! | J9: =K9/SUM($K$4:$K$18) -> #REF! | K9: =C9+E9+G9+I9 -> #REF! | M9: =#REF!+#REF!+#REF!+#REF! -> #REF! | O9: =#REF!+#REF!+#REF!+#REF! -> #REF! | Q9: =#REF!+#REF!+#REF!+#REF! -> #REF! | S9: =#REF!+#REF!+#REF!+#REF! -> #REF!
A10: 7组 | B10: =#REF! -> #REF! | C10: =#REF!+#REF!+#REF!+#REF! -> #REF! | D10: =#REF! -> #REF! | E10: =#REF!+#REF!+#REF!+#REF! -> #REF! | F10: =#REF! -> #REF! | G10: =#REF!+#REF!+#REF!+#REF! -> #REF! | H10: =#REF! -> #REF! | I10: =#REF!+#REF!+#REF!+#REF! -> #REF! | J10: =K10/SUM($K$4:$K$18) -> #REF! | K10: =C10+E10+G10+I10 -> #REF! | M10: =#REF!+#REF!+#REF!+#REF! -> #REF! | O10: =#REF!+#REF!+#REF!+#REF! -> #REF! | Q10: =#REF!+#REF!+#REF!+#REF! -> #REF! | S10: =#REF!+#REF!+#REF!+#REF! -> #REF!
A11: 8组 | B11: =#REF! -> #REF! | C11: =#REF!+#REF!+#REF!+#REF! -> #REF! | D11: =#REF! -> #REF! | E11: =#REF!+#REF!+#REF!+#REF! -> #REF! | F11: =#REF! -> #REF! | G11: =#REF!+#REF!+#REF!+#REF! -> #REF! | H11: =#REF! -> #REF! | I11: =#REF!+#REF!+#REF!+#REF! -> #REF! | J11: =K11/SUM($K$4:$K$18) -> #REF! | K11: =C11+E11+G11+I11 -> #REF! | M11: =#REF!+#REF!+#REF!+#REF! -> #REF! | O11: =#REF!+#REF!+#REF!+#REF! -> #REF! | Q11: =#REF!+#REF!+#REF!+#REF! -> #REF! | S11: =#REF!+#REF!+#REF!+#REF! -> #REF!
A12: 9组 | B12: =#REF! -> #REF! | C12: =#REF!+#REF!+#REF!+#REF! -> #REF! | D12: =#REF! -> #REF! | E12: =#REF!+#REF!+#REF!+#REF! -> #REF! | F12: =#REF! -> #REF! | G12: =#REF!+#REF!+#REF!+#REF! -> #REF! | H12: =#REF! -> #REF! | I12: =#REF!+#REF!+#REF!+#REF! -> #REF! | J12: =K12/SUM($K$4:$K$18) -> #REF! | K12: =C12+E12+G12+I12 -> #REF! | M12: =#REF!+#REF!+#REF!+#REF! -> #REF! | O12: =#REF!+#REF!+#REF!+#REF! -> #REF! | Q12: =#REF!+#REF!+#REF!+#REF! -> #REF! | S12: =#REF!+#REF!+#REF!+#REF! -> #REF!
A13: 10组 | B13: =#REF! -> #REF! | C13: =#REF!+#REF!+#REF!+#REF! -> #REF! | D13: =#REF! -> #REF! | E13: =#REF!+#REF!+#REF!+#REF! -> #REF! | F13: =#REF! -> #REF! | G13: =#REF!+#REF!+#REF!+#REF! -> #REF! | H13: =#REF! -> #REF! | I13: =#REF!+#REF!+#REF!+#REF! -> #REF! | J13: =K13/SUM($K$4:$K$18) -> #REF! | K13: =C13+E13+G13+I13 -> #REF! | M13: =#REF!+#REF!+#REF!+#REF! -> #REF! | O13: =#REF!+#REF!+#REF!+#REF! -> #REF! | Q13: =#REF!+#REF!+#REF!+#REF! -> #REF! | S13: =#REF!+#REF!+#REF!+#REF! -> #REF!
A14: 11组 | B14: =#REF! -> #REF! | C14: =#REF!+#REF!+#REF!+#REF! -> #REF! | D14: =#REF! -> #REF! | E14: =#REF!+#REF!+#REF!+#REF! -> #REF! | F14: =#REF! -> #REF! | G14: =#REF!+#REF!+#REF!+#REF! -> #REF! | H14: =#REF! -> #REF! | I14: =#REF!+#REF!+#REF!+#REF! -> #REF! | J14: =K14/SUM($K$4:$K$18) -> #REF! | K14: =C14+E14+G14+I14 -> #REF! | M14: =#REF!+#REF!+#REF!+#REF! -> #REF! | O14: =#REF!+#REF!+#REF!+#REF! -> #REF! | Q14: =#REF!+#REF!+#REF!+#REF! -> #REF! | S14: =#REF!+#REF!+#REF!+#REF! -> #REF!
A15: 12组 | B15: =#REF! -> #REF! | C15: =#REF!+#REF!+#REF!+#REF! -> #REF! | D15: =#REF! -> #REF! | E15: =#REF!+#REF!+#REF!+#REF! -> #REF! | F15: =#REF! -> #REF! | G15: =#REF!+#REF!+#REF!+#REF! -> #REF! | H15: =#REF! -> #REF! | I15: =#REF!+#REF!+#REF!+#REF! -> #REF! | J15: =K15/SUM($K$4:$K$18) -> #REF! | K15: =C15+E15+G15+I15 -> #REF! | M15: =#REF!+#REF!+#REF!+#REF! -> #REF! | O15: =#REF!+#REF!+#REF!+#REF! -> #REF! | Q15: =#REF!+#REF!+#REF!+#REF! -> #REF! | S15: =#REF!+#REF!+#REF!+#REF! -> #REF!
A16: 13组 | B16: =#REF! -> #REF! | C16: =#REF!+#REF!+#REF!+#REF! -> #REF! | D16: =#REF! -> #REF! | E16: =#REF!+#REF!+#REF!+#REF! -> #REF! | F16: =#REF! -> #REF! | G16: =#REF!+#REF!+#REF!+#REF! -> #REF! | H16: =#REF! -> #REF! | I16: =#REF!+#REF!+#REF!+#REF! -> #REF! | J16: =K16/SUM($K$4:$K$18) -> #REF! | K16: =C16+E16+G16+I16 -> #REF! | M16: =#REF!+#REF!+#REF!+#REF! -> #REF! | O16: =#REF!+#REF!+#REF!+#REF! -> #REF! | Q16: =#REF!+#REF!+#REF!+#REF! -> #REF! | S16: =#REF!+#REF!+#REF!+#REF! -> #REF!
... A18: 15组 | B18: =#REF! -> #REF! | C18: =#REF!+#REF!+#REF!+#REF! -> #REF! | D18: =#REF! -> #REF! | E18: =#REF!+#REF!+#REF!+#REF! -> #REF! | F18: =#REF! -> #REF! | G18: =#REF!+#REF!+#REF!+#REF! -> #REF! | H18: =#REF! -> #REF! | I18: =#REF!+#REF!+#REF!+#REF! -> #REF! | J18: =K18/SUM($K$4:$K$18) -> #REF! | K18: =C18+E18+G18+I18 -> #REF! | M18: =#REF!+#REF!+#REF!+#REF! -> #REF! | O18: =#REF!+#REF!+#REF!+#REF! -> #REF! | Q18: =#REF!+#REF!+#REF!+#REF! -> #REF! | S18: =#REF!+#REF!+#REF!+#REF! -> #REF!
A20: 年度 | B20: 第二年
A21: 区域 | B21: 本地 | D21: 全国 | F21: 亚太 | H21: 全球 | J21: 总计 | L21: 贸易 | N21: 集成 | P21: 服务 | R21: 科创 | X21: 第二年市占比
A22: 类别 | B22: 地位 | C22: 份额 | D22: 地位 | E22: 份额 | F22: 地位 | G22: 份额 | H22: 地位 | I22: 份额 | J22: 占比 | K22: 份额 | L22: 地位 | M22: 份额 | N22: 地位 | O22: 份额 | P22: 地位 | Q22: 份额 | R22: 地位 | S22: 份额
A23: 1组 | B23: =#REF! -> #REF! | C23: =#REF!+#REF!+#REF!+#REF! -> #REF! | D23: =#REF! -> #REF! | E23: =#REF!+#REF!+#REF!+#REF! -> #REF! | F23: =#REF! -> #REF! | G23: =#REF!+#REF!+#REF!+#REF! -> #REF! | H23: =#REF! -> #REF! | I23: =#REF!+#REF!+#REF!+#REF! -> #REF! | J23: =K23/SUM($K$23:$K$37) -> #REF! | K23: =C23+E23+G23+I23 -> #REF! | M23: =#REF!+#REF!+#REF!+#REF! -> #REF! | O23: =#REF!+#REF!+#REF!+#REF! -> #REF! | Q23: =#REF!+#REF!+#REF!+#REF! -> #REF! | S23: =#REF!+#REF!+#REF!+#REF! -> #REF!
A24: 2组 | B24: =#REF! -> #REF! | C24: =#REF!+#REF!+#REF!+#REF! -> #REF! | D24: =#REF! -> #REF! | E24: =#REF!+#REF!+#REF!+#REF! -> #REF! | F24: =#REF! -> #REF! | G24: =#REF!+#REF!+#REF!+#REF! -> #REF! | H24: =#REF! -> #REF! | I24: =#REF!+#REF!+#REF!+#REF! -> #REF! | J24: =K24/SUM($K$23:$K$37) -> #REF! | K24: =C24+E24+G24+I24 -> #REF! | M24: =#REF!+#REF!+#REF!+#REF! -> #REF! | O24: =#REF!+#REF!+#REF!+#REF! -> #REF! | Q24: =#REF!+#REF!+#REF!+#REF! -> #REF! | S24: =#REF!+#REF!+#REF!+#REF! -> #REF!
A25: 3组 | B25: =#REF! -> #REF! | C25: =#REF!+#REF!+#REF!+#REF! -> #REF! | D25: =#REF! -> #REF! | E25: =#REF!+#REF!+#REF!+#REF! -> #REF! | F25: =#REF! -> #REF! | G25: =#REF!+#REF!+#REF!+#REF! -> #REF! | H25: =#REF! -> #REF! | I25: =#REF!+#REF!+#REF!+#REF! -> #REF! | J25: =K25/SUM($K$23:$K$37) -> #REF! | K25: =C25+E25+G25+I25 -> #REF! | M25: =#REF!+#REF!+#REF!+#REF! -> #REF! | O25: =#REF!+#REF!+#REF!+#REF! -> #REF! | Q25: =#REF!+#REF!+#REF!+#REF! -> #REF! | S25: =#REF!+#REF!+#REF!+#REF! -> #REF!
A26: 4组 | B26: =#REF! -> #REF! | C26: =#REF!+#REF!+#REF!+#REF! -> #REF! | D26: =#REF! -> #REF! | E26: =#REF!+#REF!+#REF!+#REF! -> #REF! | F26: =#REF! -> #REF! | G26: =#REF!+#REF!+#REF!+#REF! -> #REF! | H26: =#REF! -> #REF! | I26: =#REF!+#REF!+#REF!+#REF! -> #REF! | J26: =K26/SUM($K$23:$K$37) -> #REF! | K26: =C26+E26+G26+I26 -> #REF! | M26: =#REF!+#REF!+#REF!+#REF! -> #REF! | O26: =#REF!+#REF!+#REF!+#REF! -> #REF! | Q26: =#REF!+#REF!+#REF!+#REF! -> #REF! | S26: =#REF!+#REF!+#REF!+#REF! -> #REF!
A27: 5组 | B27: =#REF! -> #REF! | C27: =#REF!+#REF!+#REF!+#REF! -> #REF! | D27: =#REF! -> #REF! | E27: =#REF!+#REF!+#REF!+#REF! -> #REF! | F27: =#REF! -> #REF! | G27: =#REF!+#REF!+#REF!+#REF! -> #REF! | H27: =#REF! -> #REF! | I27: =#REF!+#REF!+#REF!+#REF! -> #REF! | J27: =K27/SUM($K$23:$K$37) -> #REF! | K27: =C27+E27+G27+I27 -> #REF! | M27: =#REF!+#REF!+#REF!+#REF! -> #REF! | O27: =#REF!+#REF!+#REF!+#REF! -> #REF! | Q27: =#REF!+#REF!+#REF!+#REF! -> #REF! | S27: =#REF!+#REF!+#REF!+#REF! -> #REF!
A28: 6组 | B28: =#REF! -> #REF! | C28: =#REF!+#REF!+#REF!+#REF! -> #REF! | D28: =#REF! -> #REF! | E28: =#REF!+#REF!+#REF!+#REF! -> #REF! | F28: =#REF! -> #REF! | G28: =#REF!+#REF!+#REF!+#REF! -> #REF! | H28: =#REF! -> #REF! | I28: =#REF!+#REF!+#REF!+#REF! -> #REF! | J28: =K28/SUM($K$23:$K$37) -> #REF! | K28: =C28+E28+G28+I28 -> #REF! | M28: =#REF!+#REF!+#REF!+#REF! -> #REF! | O28: =#REF!+#REF!+#REF!+#REF! -> #REF! | Q28: =#REF!+#REF!+#REF!+#REF! -> #REF! | S28: =#REF!+#REF!+#REF!+#REF! -> #REF!
A29: 7组 | B29: =#REF! -> #REF! | C29: =#REF!+#REF!+#REF!+#REF! -> #REF! | D29: =#REF! -> #REF! | E29: =#REF!+#REF!+#REF!+#REF! -> #REF! | F29: =#REF! -> #REF! | G29: =#REF!+#REF!+#REF!+#REF! -> #REF! | H29: =#REF! -> #REF! | I29: =#REF!+#REF!+#REF!+#REF! -> #REF! | J29: =K29/SUM($K$23:$K$37) -> #REF! | K29: =C29+E29+G29+I29 -> #REF! | M29: =#REF!+#REF!+#REF!+#REF! -> #REF! | O29: =#REF!+#REF!+#REF!+#REF! -> #REF! | Q29: =#REF!+#REF!+#REF!+#REF! -> #REF! | S29: =#REF!+#REF!+#REF!+#REF! -> #REF!
A30: 8组 | B30: =#REF! -> #REF! | C30: =#REF!+#REF!+#REF!+#REF! -> #REF! | D30: =#REF! -> #REF! | E30: =#REF!+#REF!+#REF!+#REF! -> #REF! | F30: =#REF! -> #REF! | G30: =#REF!+#REF!+#REF!+#REF! -> #REF! | H30: =#REF! -> #REF! | I30: =#REF!+#REF!+#REF!+#REF! -> #REF! | J30: =K30/SUM($K$23:$K$37) -> #REF! | K30: =C30+E30+G30+I30 -> #REF! | M30: =#REF!+#REF!+#REF!+#REF! -> #REF! | O30: =#REF!+#REF!+#REF!+#REF! -> #REF! | Q30: =#REF!+#REF!+#REF!+#REF! -> #REF! | S30: =#REF!+#REF!+#REF!+#REF! -> #REF!
A31: 9组 | B31: =#REF! -> #REF! | C31: =#REF!+#REF!+#REF!+#REF! -> #REF! | D31: =#REF! -> #REF! | E31: =#REF!+#REF!+#REF!+#REF! -> #REF! | F31: =#REF! -> #REF! | G31: =#REF!+#REF!+#REF!+#REF! -> #REF! | H31: =#REF! -> #REF! | I31: =#REF!+#REF!+#REF!+#REF! -> #REF! | J31: =K31/SUM($K$23:$K$37) -> #REF! | K31: =C31+E31+G31+I31 -> #REF! | M31: =#REF!+#REF!+#REF!+#REF! -> #REF! | O31: =#REF!+#REF!+#REF!+#REF! -> #REF! | Q31: =#REF!+#REF!+#REF!+#REF! -> #REF! | S31: =#REF!+#REF!+#REF!+#REF! -> #REF!
A32: 10组 | B32: =#REF! -> #REF! | C32: =#REF!+#REF!+#REF!+#REF! -> #REF! | D32: =#REF! -> #REF! | E32: =#REF!+#REF!+#REF!+#REF! -> #REF! | F32: =#REF! -> #REF! | G32: =#REF!+#REF!+#REF!+#REF! -> #REF! | H32: =#REF! -> #REF! | I32: =#REF!+#REF!+#REF!+#REF! -> #REF! | J32: =K32/SUM($K$23:$K$37) -> #REF! | K32: =C32+E32+G32+I32 -> #REF! | M32: =#REF!+#REF!+#REF!+#REF! -> #REF! | O32: =#REF!+#REF!+#REF!+#REF! -> #REF! | Q32: =#REF!+#REF!+#REF!+#REF! -> #REF! | S32: =#REF!+#REF!+#REF!+#REF! -> #REF!
A33: 11组 | B33: =#REF! -> #REF! | C33: =#REF!+#REF!+#REF!+#REF! -> #REF! | D33: =#REF! -> #REF! | E33: =#REF!+#REF!+#REF!+#REF! -> #REF! | F33: =#REF! -> #REF! | G33: =#REF!+#REF!+#REF!+#REF! -> #REF! | H33: =#REF! -> #REF! | I33: =#REF!+#REF!+#REF!+#REF! -> #REF! | J33: =K33/SUM($K$23:$K$37) -> #REF! | K33: =C33+E33+G33+I33 -> #REF! | M33: =#REF!+#REF!+#REF!+#REF! -> #REF! | O33: =#REF!+#REF!+#REF!+#REF! -> #REF! | Q33: =#REF!+#REF!+#REF!+#REF! -> #REF! | S33: =#REF!+#REF!+#REF!+#REF! -> #REF!
A34: 12组 | B34: =#REF! -> #REF! | C34: =#REF!+#REF!+#REF!+#REF! -> #REF! | D34: =#REF! -> #REF! | E34: =#REF!+#REF!+#REF!+#REF! -> #REF! | F34: =#REF! -> #REF! | G34: =#REF!+#REF!+#REF!+#REF! -> #REF! | H34: =#REF! -> #REF! | I34: =#REF!+#REF!+#REF!+#REF! -> #REF! | J34: =K34/SUM($K$23:$K$37) -> #REF! | K34: =C34+E34+G34+I34 -> #REF! | M34: =#REF!+#REF!+#REF!+#REF! -> #REF! | O34: =#REF!+#REF!+#REF!+#REF! -> #REF! | Q34: =#REF!+#REF!+#REF!+#REF! -> #REF! | S34: =#REF!+#REF!+#REF!+#REF! -> #REF!
... A37: 15组 | B37: =#REF! -> #REF! | C37: =#REF!+#REF!+#REF!+#REF! -> #REF! | D37: =#REF! -> #REF! | E37: =#REF!+#REF!+#REF!+#REF! -> #REF! | F37: =#REF! -> #REF! | G37: =#REF!+#REF!+#REF!+#REF! -> #REF! | H37: =#REF! -> #REF! | I37: =#REF!+#REF!+#REF!+#REF! -> #REF! | J37: =K37/SUM($K$23:$K$37) -> #REF! | K37: =C37+E37+G37+I37 -> #REF! | M37: =#REF!+#REF!+#REF!+#REF! -> #REF! | O37: =#REF!+#REF!+#REF!+#REF! -> #REF! | Q37: =#REF!+#REF!+#REF!+#REF! -> #REF! | S37: =#REF!+#REF!+#REF!+#REF! -> #REF!
A39: 年度 | B39: 第三年
A40: 区域 | B40: 本地 | D40: 全国 | F40: 亚太 | H40: 全球 | J40: 总计 | L40: 贸易 | N40: 集成 | P40: 服务 | R40: 科创
A41: 类别 | B41: 地位 | C41: 份额 | D41: 地位 | E41: 份额 | F41: 地位 | G41: 份额 | H41: 地位 | I41: 份额 | J41: 占比 | K41: 份额 | L41: 地位 | M41: 份额 | N41: 地位 | O41: 份额 | P41: 地位 | Q41: 份额 | R41: 地位 | S41: 份额 | X41: 第三年市占比
A42: 1组 | B42: =#REF! -> #REF! | C42: =#REF!+#REF!+#REF!+#REF! -> #REF! | D42: =#REF! -> #REF! | E42: =#REF!+#REF!+#REF!+#REF! -> #REF! | F42: =#REF! -> #REF! | G42: =#REF!+#REF!+#REF!+#REF! -> #REF! | H42: =#REF! -> #REF! | I42: =#REF!+#REF!+#REF!+#REF! -> #REF! | J42: =K42/SUM($K$42:$K$56) -> #REF! | K42: =C42+E42+G42+I42 -> #REF! | M42: =#REF!+#REF!+#REF!+#REF! -> #REF! | O42: =P62 -> 0 | Q42: =#REF!+#REF!+#REF!+#REF! -> #REF! | S42: =#REF!+#REF!+#REF!+#REF! -> #REF!
A43: 2组 | B43: =#REF! -> #REF! | C43: =#REF!+#REF!+#REF!+#REF! -> #REF! | D43: =#REF! -> #REF! | E43: =#REF!+#REF!+#REF!+#REF! -> #REF! | F43: =#REF! -> #REF! | G43: =#REF!+#REF!+#REF!+#REF! -> #REF! | H43: =#REF! -> #REF! | I43: =#REF!+#REF!+#REF!+#REF! -> #REF! | J43: =K43/SUM($K$42:$K$56) -> #REF! | K43: =C43+E43+G43+I43 -> #REF! | M43: =#REF!+#REF!+#REF!+#REF! -> #REF! | O43: =#REF!+#REF!+#REF!+#REF! -> #REF! | Q43: =#REF!+#REF!+#REF!+#REF! -> #REF! | S43: =#REF!+#REF!+#REF!+#REF! -> #REF!
A44: 3组 | B44: =#REF! -> #REF! | C44: =#REF!+#REF!+#REF!+#REF! -> #REF! | D44: =#REF! -> #REF! | E44: =#REF!+#REF!+#REF!+#REF! -> #REF! | F44: =#REF! -> #REF! | G44: =#REF!+#REF!+#REF!+#REF! -> #REF! | H44: =#REF! -> #REF! | I44: =#REF!+#REF!+#REF!+#REF! -> #REF! | J44: =K44/SUM($K$42:$K$56) -> #REF! | K44: =C44+E44+G44+I44 -> #REF! | M44: =#REF!+#REF!+#REF!+#REF! -> #REF! | O44: =#REF!+#REF!+#REF!+#REF! -> #REF! | Q44: =#REF!+#REF!+#REF!+#REF! -> #REF! | S44: =#REF!+#REF!+#REF!+#REF! -> #REF!
A45: 4组 | B45: =#REF! -> #REF! | C45: =#REF!+#REF!+#REF!+#REF! -> #REF! | D45: =#REF! -> #REF! | E45: =#REF!+#REF!+#REF!+#REF! -> #REF! | F45: =#REF! -> #REF! | G45: =#REF!+#REF!+#REF!+#REF! -> #REF! | H45: =#REF! -> #REF! | I45: =#REF!+#REF!+#REF!+#REF! -> #REF! | J45: =K45/SUM($K$42:$K$56) -> #REF! | K45: =C45+E45+G45+I45 -> #REF! | M45: =#REF!+#REF!+#REF!+#REF! -> #REF! | O45: =#REF!+#REF!+#REF!+#REF! -> #REF! | Q45: =#REF!+#REF!+#REF!+#REF! -> #REF! | S45: =#REF!+#REF!+#REF!+#REF! -> #REF!
...

Sheet 市场预测
A1: 市场预测（1-3年）
L2: 本地市场 | P2: 区域市场 | T2: 全国市场 | X2: 全球市场
F3: 第一年：以代办过检为核心冲顶销量，稳居本地市场主力；两舱贵宾初步试水，贵宾及会员定制尚未布局，以高性价比代检产品快速打开市场、建立认知。 第二年：代办过检销量回落但仍占主导，两舱贵宾翻倍增长成第二增长曲线，商务贵宾零到一突破，会员定制启动布局，产品由单一转向多元梯队。 第三年：代办过检持续下滑，两舱贵宾规模稳定，商务贵宾反超成增长核心，会员定制规模化落地，形成托底 — 稳盘 — 引领的成熟结构，实现从规模扩张到价值升级，筑牢区域壁垒。 | K3: 年度 | L3: 代办过检 | M3: 两舱贵宾 | N3: 商务贵宾 | O3: 会员定制 | P3: 代办过检 | Q3: 两舱贵宾 | R3: 商务贵宾 | S3: 会员定制 | T3: 代办过检 | U3: 两舱贵宾 | V3: 商务贵宾 | W3: 会员定制 | X3: 代办过检 | Y3: 两舱贵宾 | Z3: 商务贵宾 | AA3: 会员定制
J4: 市场总量 | K4: 第一年 | L4: ='1年本地'!V23 -> 169 | M4: ='1年本地'!V46 -> 13 | N4: ='1年本地'!V69 -> 0 | O4: ='1年本地'!V92 -> 0 | P4: ='1年区域'!V23 -> 0 | Q4: ='1年区域'!V46 -> 0 | R4: ='1年区域'!V69 -> 0 | S4: ='1年区域'!V92 -> 0 | T4: ='1年全国'!V23 -> 0 | U4: ='1年全国'!V46 -> 0 | V4: ='1年全国'!V69 -> 0 | W4: ='1年全国'!V92 -> 0 | X4: ='1年全球'!V23 -> 0 | Y4: ='1年全球'!V46 -> 0 | Z4: ='1年全球'!V69 -> 0 | AA4: ='1年全球'!V92 -> 0
K5: 第二年 | L5: ='2年本地'!V23 -> 79 | M5: ='2年本地'!V46 -> 41 | N5: ='2年本地'!V69 -> 0 | O5: ='2年本地'!V92 -> 0 | P5: ='2年区域'!V23 -> 87 | Q5: ='2年区域'!V46 -> 39 | R5: ='2年区域'!V69 -> 0 | S5: ='2年区域'!V92 -> 0 | T5: ='2年全国'!V23 -> 0 | U5: ='2年全国'!V46 -> 0 | V5: ='2年全国'!V69 -> 0 | W5: ='2年全国'!V92 -> 0 | X5: ='2年全球'!V23 -> 0 | Y5: ='2年全球'!V46 -> 0 | Z5: ='2年全球'!V69 -> 0 | AA5: ='2年全球'!V92 -> 0
K6: 第三年 | L6: ='3年本地'!V23 -> 30 | M6: ='3年本地'!V46 -> 36 | N6: ='3年本地'!V69 -> 48 | O6: ='3年本地'!V92 -> 33 | P6: ='3年区域'!V23 -> 52.5 | Q6: ='3年区域'!V46 -> 50 | R6: ='3年区域'!V69 -> 18 | S6: ='3年区域'!V92 -> 58.5 | T6: ='3年全国'!V23 -> 131 | U6: ='3年全国'!V46 -> 111 | V6: ='3年全国'!V69 -> 89 | W6: ='3年全国'!V92 -> 36 | X6: ='3年全球'!V23 -> 0 | Y6: ='3年全球'!V46 -> 0 | Z6: ='3年全球'!V69 -> 0 | AA6: ='3年全球'!V92 -> 0
K7: 第四年 | L7: ='4年本地'!V23 -> 45 | M7: ='4年本地'!V46 -> 57 | N7: ='4年本地'!V69 -> 48 | O7: ='4年本地'!V92 -> 76 | P7: ='4年区域'!V23 -> 54 | Q7: ='4年区域'!V46 -> 53 | R7: ='4年区域'!V69 -> 66 | S7: ='4年区域'!V92 -> 69 | T7: ='4年全国'!V23 -> 36 | U7: ='4年全国'!V46 -> 90 | V7: ='4年全国'!V69 -> 54 | W7: ='4年全国'!V92 -> 72 | X7: ='4年全球'!V23 -> 57 | Y7: ='4年全球'!V46 -> 89 | Z7: ='4年全球'!V69 -> 60 | AA7: ='4年全球'!V92 -> 66
K8: 第五年 | L8: ='5年本地'!V23 -> 15 | M8: ='5年本地'!V46 -> 54 | N8: ='5年本地'!V69 -> 110 | O8: ='5年本地'!V92 -> 109 | P8: ='5年区域'!V23 -> 16.5 | Q8: ='5年区域'!V46 -> 33.5 | R8: ='5年区域'!V69 -> 102 | S8: ='5年区域'!V92 -> 114 | T8: ='5年全国'!V23 -> 23 | U8: ='5年全国'!V46 -> 63 | V8: ='5年全国'!V69 -> 97 | W8: ='5年全国'!V92 -> 141 | X8: ='5年全球'!V23 -> 48 | Y8: ='5年全球'!V46 -> 79 | Z8: ='5年全球'!V69 -> 111 | AA8: ='5年全球'!V92 -> 117
K9: 第六年 | L9: ='6年本地'!V23 -> 15 | M9: ='6年本地'!V46 -> 54 | N9: ='6年本地'!V69 -> 110 | O9: ='6年本地'!V92 -> 122 | P9: ='6年区域'!V23 -> 12 | Q9: ='6年区域'!V46 -> 53 | R9: ='6年区域'!V69 -> 109.5 | S9: ='6年区域'!V92 -> 127.5 | T9: ='6年全国'!V23 -> 18 | U9: ='6年全国'!V46 -> 51 | V9: ='6年全国'!V69 -> 100 | W9: ='6年全国'!V92 -> 122 | X9: ='6年全球'!V23 -> 21 | Y9: ='6年全球'!V46 -> 79 | Z9: ='6年全球'!V69 -> 129 | AA9: ='6年全球'!V92 -> 132
K10: 第七年 | L10: ='7年本地'!V23 -> 19 | M10: ='7年本地'!V46 -> 46 | N10: ='7年本地'!V69 -> 113 | O10: ='7年本地'!V92 -> 109 | P10: ='7年区域'!V23 -> 33 | Q10: ='7年区域'!V46 -> 39 | R10: ='7年区域'!V69 -> 109.5 | S10: ='7年区域'!V92 -> 93 | T10: ='7年全国'!V23 -> 13 | U10: ='7年全国'!V46 -> 57 | V10: ='7年全国'!V69 -> 108 | W10: ='7年全国'!V92 -> 75 | X10: ='7年全球'!V23 -> 21 | Y10: ='7年全球'!V46 -> 65 | Z10: ='7年全球'!V69 -> 141 | AA10: ='7年全球'!V92 -> 129
F11: 第一年：市场启动阶段，四类产品尚未形成有效销量，重点开展调研、建渠道、树品牌，为产品落地夯实基础。 第二年：代办过检率先规模化突破，成为核心增长引擎；两舱贵宾同步放量，贵宾与会员定制完成试点破零，搭建完整产品矩阵，快速抢占区域市场。 第三年：代办过检小幅回落仍为主力，两舱与商务贵宾稳步增长；会员定制实现跨越式反超，成为新增长极，形成 “规模 + 价值” 双轮驱动格局，完成市场深度渗透与品牌占位。 | K11: 第八年 | L11: ='8年本地'!V23 -> 0 | M11: ='8年本地'!V46 -> 41 | N11: ='8年本地'!V69 -> 120 | O11: ='8年本地'!V92 -> 122 | P11: ='8年区域'!V23 -> 12 | Q11: ='8年区域'!V46 -> 69.5 | R11: ='8年区域'!V69 -> 127.5 | S11: ='8年区域'!V92 -> 138 | T11: ='8年全国'!V23 -> 23 | U11: ='8年全国'!V46 -> 42 | V11: ='8年全国'!V69 -> 151 | W11: ='8年全国'!V92 -> 155 | X11: ='8年全球'!V23 -> 15 | Y11: ='8年全球'!V46 -> 48 | Z11: ='8年全球'!V69 -> 129 | AA11: ='8年全球'!V92 -> 120
J13: 控制台
N14: 公司数量： | O14: 8
K15: 本地市场
K16: 年度 | L16: 代检数量控制 | M16: 两舱数量控制 | N16: 贵宾数量控制 | O16: 定制数量控制 | P16: 订单总数 | R16: 年度订单总数 | S16: 数量
K17: 第一年 | L17: 11 | M17: 1 | N17: 0 | O17: 0 | P17: =SUM(L17:O17) -> 12 | R17: 第一年 | S17: =P17+P27+P37+P47 -> 12
K18: 第二年 | L18: 5 | M18: 2 | N18: 0 | O18: 0 | P18: =SUM(L18:O18) -> 7 | R18: 第二年 | S18: =P18+P28+P38+P48 -> 14
F19: 前两年：全国市场筹备阶段，四类产品尚未规模化起量，重点搭建渠道网络、完善两舱体系、开展品牌推广，为全面爆发夯实基础。 第三年：全国市场全面起量，代办过检规模领跑、支撑核心销量，两舱贵宾形成第二增长曲线，商务贵宾规模化落地、会员定制破零，构建 “全国铺量 + 高端占位” 布局，树立行业影响力。 | K19: 第三年 | L19: 2 | M19: 2 | N19: 2 | O19: 1 | P19: =SUM(L19:O19) -> 7 | R19: 第三年 | S19: =P19+P29+P39+P49 -> 32
K20: 第四年 | L20: 3 | M20: 4 | N20: 2 | O20: 2 | P20: =SUM(L20:O20) -> 11 | R20: 第四年 | S20: =P20+P30+P40+P50 -> 42
K21: 第五年 | L21: 1 | M21: 3 | N21: 4 | O21: 3 | P21: =SUM(L21:O21) -> 11 | R21: 第五年 | S21: =P21+P31+P41+P51 -> 43
K22: 第六年 | L22: 1 | M22: 3 | N22: 4 | O22: 4 | P22: =SUM(L22:O22) -> 12 | R22: 第六年 | S22: =P22+P32+P42+P52 -> 48
K23: 第七年 | L23: 1 | M23: 2 | N23: 5 | O23: 3 | P23: =SUM(L23:O23) -> 11 | R23: 第七年 | S23: =P23+P33+P43+P53 -> 45
K24: 第八年 | L24: 0 | M24: 2 | N24: 5 | O24: 4 | P24: =SUM(L24:O24) -> 11 | R24: 第八年 | S24: =P24+P34+P44+P54 -> 47
K25: 区域市场
K26: 年度 | L26: 代检数量控制 | M26: 两舱数量控制 | N26: 贵宾数量控制 | O26: 定制数量控制 | P26: 订单总数
F27: 第一年、第二年、第三年：全球市场四类产品均未实现有效销量，核心聚焦国际市场调研、海外合规体系搭建、跨境渠道布局、国际品牌推广，为后续产品出海、全球市场拓展做足前期准备。 | K27: 第一年 | L27: 0 | M27: 0 | N27: 0 | O27: 0 | P27: =SUM(L27:O27) -> 0
K28: 第二年 | L28: 5 | M28: 2 | N28: 0 | O28: 0 | P28: =SUM(L28:O28) -> 7
K29: 第三年 | L29: 4 | M29: 2 | N29: 1 | O29: 2 | P29: =SUM(L29:O29) -> 9
K30: 第四年 | L30: 3 | M30: 3 | N30: 2 | O30: 2 | P30: =SUM(L30:O30) -> 10
K31: 第五年 | L31: 1 | M31: 2 | N31: 4 | O31: 3 | P31: =SUM(L31:O31) -> 10
K32: 第六年 | L32: 1 | M32: 3 | N32: 4 | O32: 4 | P32: =SUM(L32:O32) -> 12
K33: 第七年 | L33: 2 | M33: 2 | N33: 4 | O33: 3 | P33: =SUM(L33:O33) -> 11
K34: 第八年 | L34: 1 | M34: 3 | N34: 5 | O34: 4 | P34: =SUM(L34:O34) -> 13
A35: 市场预测（4-5年） | K35: 全国市场
K36: 年度 | L36: 代检数量控制 | M36: 两舱数量控制 | N36: 贵宾数量控制 | O36: 定制数量控制 | P36: 订单总数
F37: 第四年：代办过检为本地销量主力，两舱贵宾紧随其后，商务贵宾与会员定制初步放量，形成 “代检 + 两舱” 双主力、高端产品补位的多元格局。 第五年：代检与两舱贵宾销量回落、角色转为辅助；商务贵宾跨越式增长成核心，会员定制同步放量，形成 “双高端引领” 格局，市场实现从规模到价值的升级。 | K37: 第一年 | L37: 0 | M37: 0 | N37: 0 | O37: 0 | P37: =SUM(L37:O37) -> 0
K38: 第二年 | L38: 0 | M38: 0 | N38: 0 | O38: 0 | P38: =SUM(L38:O38) -> 0
K39: 第三年 | L39: 7 | M39: 5 | N39: 3 | O39: 1 | P39: =SUM(L39:O39) -> 16
K40: 第四年 | L40: 2 | M40: 4 | N40: 2 | O40: 2 | P40: =SUM(L40:O40) -> 10
K41: 第五年 | L41: 1 | M41: 3 | N41: 3 | O41: 3 | P41: =SUM(L41:O41) -> 10
...

Sheet 1年本地
AF1: 上年市场地位 | AG1: 组号 | AH1: 市场地位 | AJ1: 本年市场地位 | AK1: 组号 | AL1: 订单总额 | AM1: 市场投入 | AN1: 市场地位 | AP1: 组号 | AQ1: 代办过检 | AR1: 代办过检市场投入 | AS1: 两舱贵宾 | AT1: 两舱贵宾市场投入 | AU1: 商务贵宾 | AV1: 商务贵宾市场投入 | AW1: 会员定制 | AX1: 会员定制市场投入
B2: 代办过检 | H2: 代办过检 | N2: 代办过检 | T2: 代办过检 | Z2: 代办过检
B3: 总额 ： | C3: =IF(C4>0,J22*C4-P22*(C4-((D23+J23)/2)),0) -> 15 | D3: M | F3: 第一年：以代办过检为绝对核心，销量规模达到峰值，是本地市场的绝对主力；两舱贵宾仅实现小规模起步，贵宾、会员定制尚未形成有效布局，整体以低门槛、高性价比的代检款打开本地市场，快速建立客户认知与渠道覆盖。 第二年：代办过检销量较第一年明显回落，但仍保持市场主导地位；两舱贵宾实现翻倍式增长，成为本地市场第二增长曲线；商务贵宾完成从 0 到 1 的突破，会员定制同步启动布局，产品结构从 “单一代检款” 向 “多元梯队” 转型，适配本地客户的分层需求。 第三年：代办过检销量持续下行，两舱贵宾规模保持稳定，商务贵宾销量反超两舱贵宾，成为本地市场增长核心；会员定制实现规模化落地，形成 “代办过检托底、两舱贵宾稳盘、贵宾 + 会员定制引领增长” 的成熟结构，完成本地市场从 “规模扩张” 到 “价值升级” 的转型，筑牢区域竞争壁垒。 | H3: 总额 ： | I3: =IF(I4>0,J22*I4-P22*(I4-((D23+J23)/2)),0) -> 11 | J3: M | N3: 总额 ： | O3: =IF(O4>0,J22*O4-P22*(O4-((D23+J23)/2)),0) -> 11 | P3: M | T3: 总额 ： | U3: =IF(U4>0,J22*U4-P22*(U4-((D23+J23)/2)),0) -> 15 | V3: M | Z3: 总额 ： | AA3: =IF(AA4>0,J22*AA4-P22*(AA4-((D23+J23)/2)),0) -> 15 | AB3: M | AG3: 1组 | AK3: 1组 | AL3: =AQ3+AS3+AU3+AW3 -> 0 | AM3: =AR3+AT3+AV3+AX3 -> 0 | AP3: 1 | AQ3: =IF(E4=AP3,C3,0)+IF(K4=AP3,I3,0)+IF(Q4=AP3,O3,0)++IF(W4=AP3,U3,0)+IF(AC4=AP3,AA3,0)+IF(E11=AP3,C10,0)+IF(K11=AP3,I10,0)+IF(Q11=AP3,O10,0)+IF(W11=AP3,U10,0)+IF(AC11=AP3,AA10,0)+IF(E18=AP3,C17,0)+IF(K18=AP3,I17,0)+IF(Q18=AP3,O17,0)+IF(W18=AP3,U17,0)+IF(AC18=AP3,AA17,0) -> 0 | AS3: =IF(E27=AP3,C26,0)+IF(K27=AP3,I26,0)+IF(Q27=AP3,O26,0)++IF(W27=AP3,U26,0)+IF(AC27=AP3,AA26,0)+IF(E34=AP3,C33,0)+IF(K34=AP3,I33,0)+IF(Q34=AP3,O33,0)+IF(W34=AP3,U33,0)+IF(AC34=AP3,AA33,0)+IF(E41=AP3,C40,0)+IF(K41=AP3,I40,0)+IF(Q41=AP3,O40,0)+IF(W41=AP3,U40,0)+IF(AC41=AP3,AA40,0) -> 0 | AU3: =IF(E50=AP3,C49,0)+IF(K50=AP3,I49,0)+IF(Q50=AP3,O49,0)++IF(W50=AP3,U49,0)+IF(AC50=AP3,AA49,0)+IF(E57=AP3,C56,0)+IF(K57=AP3,I56,0)+IF(Q57=AP3,O56,0)+IF(W57=AP3,U56,0)+IF(AC57=AP3,AA56,0)+IF(E64=AP3,C63,0)+IF(K64=AP3,I63,0)+IF(Q64=AP3,O63,0)+IF(W64=AP3,U63,0)+IF(AC64=AP3,AA63,0) -> 0 | AW3: =IF(E73=AP3,C72,0)+IF(K73=AP3,I72,0)+IF(Q73=AP3,O72,0)++IF(W73=AP3,U72,0)+IF(AC73=AP3,AA72,0)+IF(E80=AP3,C79,0)+IF(K80=AP3,I79,0)+IF(Q80=AP3,O79,0)+IF(W80=AP3,U79,0)+IF(AC80=AP3,AA79,0)+IF(E87=AP3,C86,0)+IF(K87=AP3,I86,0)+IF(Q87=AP3,O86,0)+IF(W87=AP3,U86,0)+IF(AC87=AP3,AA86,0) -> 0
B4: 数量 ： | C4: =IF(D22>=1,RANDBETWEEN(D23,J23),0) -> 3 | H4: 数量 ： | I4: =IF(D22>=2,RANDBETWEEN(D23,J23),0) -> 2 | N4: 数量 ： | O4: =IF(D22>=3,RANDBETWEEN(D23,J23),0) -> 2 | T4: 数量 ： | U4: =IF(D22>=4,RANDBETWEEN(D23,J23),0) -> 3 | Z4: 数量 ： | AA4: =IF(D22>=5,RANDBETWEEN(D23,J23),0) -> 3 | AG4: 2组 | AK4: 2组 | AL4: =AQ4+AS4+AU4+AW4 -> 0 | AM4: =AR4+AT4+AV4+AX4 -> 0 | AP4: 2 | AQ4: =IF(E4=AP4,C3,0)+IF(K4=AP4,I3,0)+IF(Q4=AP4,O3,0)++IF(W4=AP4,U3,0)+IF(AC4=AP4,AA3,0)+IF(E11=AP4,C10,0)+IF(K11=AP4,I10,0)+IF(Q11=AP4,O10,0)+IF(W11=AP4,U10,0)+IF(AC11=AP4,AA10,0)+IF(E18=AP4,C17,0)+IF(K18=AP4,I17,0)+IF(Q18=AP4,O17,0)+IF(W18=AP4,U17,0)+IF(AC18=AP4,AA17,0) -> 0 | AS4: =IF(E27=AP4,C26,0)+IF(K27=AP4,I26,0)+IF(Q27=AP4,O26,0)++IF(W27=AP4,U26,0)+IF(AC27=AP4,AA26,0)+IF(E34=AP4,C33,0)+IF(K34=AP4,I33,0)+IF(Q34=AP4,O33,0)+IF(W34=AP4,U33,0)+IF(AC34=AP4,AA33,0)+IF(E41=AP4,C40,0)+IF(K41=AP4,I40,0)+IF(Q41=AP4,O40,0)+IF(W41=AP4,U40,0)+IF(AC41=AP4,AA40,0) -> 0 | AU4: =IF(E50=AP4,C49,0)+IF(K50=AP4,I49,0)+IF(Q50=AP4,O49,0)++IF(W50=AP4,U49,0)+IF(AC50=AP4,AA49,0)+IF(E57=AP4,C56,0)+IF(K57=AP4,I56,0)+IF(Q57=AP4,O56,0)+IF(W57=AP4,U56,0)+IF(AC57=AP4,AA56,0)+IF(E64=AP4,C63,0)+IF(K64=AP4,I63,0)+IF(Q64=AP4,O63,0)+IF(W64=AP4,U63,0)+IF(AC64=AP4,AA63,0) -> 0 | AW4: =IF(E73=AP4,C72,0)+IF(K73=AP4,I72,0)+IF(Q73=AP4,O72,0)++IF(W73=AP4,U72,0)+IF(AC73=AP4,AA72,0)+IF(E80=AP4,C79,0)+IF(K80=AP4,I79,0)+IF(Q80=AP4,O79,0)+IF(W80=AP4,U79,0)+IF(AC80=AP4,AA79,0)+IF(E87=AP4,C86,0)+IF(K87=AP4,I86,0)+IF(Q87=AP4,O86,0)+IF(W87=AP4,U86,0)+IF(AC87=AP4,AA86,0) -> 0
B5: 单价 ： | C5: =C3/C4 -> 5 | D5: M | H5: 单价 ： | I5: =I3/I4 -> 5.5 | J5: M | N5: 单价 ： | O5: =O3/O4 -> 5.5 | P5: M | T5: 单价 ： | U5: =U3/U4 -> 5 | V5: M | Z5: 单价 ： | AA5: =AA3/AA4 -> 5 | AB5: M | AG5: 3组 | AK5: 3组 | AL5: =AQ5+AS5+AU5+AW5 -> 0 | AM5: =AR5+AT5+AV5+AX5 -> 0 | AP5: 3 | AQ5: =IF(E4=AP5,C3,0)+IF(K4=AP5,I3,0)+IF(Q4=AP5,O3,0)++IF(W4=AP5,U3,0)+IF(AC4=AP5,AA3,0)+IF(E11=AP5,C10,0)+IF(K11=AP5,I10,0)+IF(Q11=AP5,O10,0)+IF(W11=AP5,U10,0)+IF(AC11=AP5,AA10,0)+IF(E18=AP5,C17,0)+IF(K18=AP5,I17,0)+IF(Q18=AP5,O17,0)+IF(W18=AP5,U17,0)+IF(AC18=AP5,AA17,0) -> 0 | AS5: =IF(E27=AP5,C26,0)+IF(K27=AP5,I26,0)+IF(Q27=AP5,O26,0)++IF(W27=AP5,U26,0)+IF(AC27=AP5,AA26,0)+IF(E34=AP5,C33,0)+IF(K34=AP5,I33,0)+IF(Q34=AP5,O33,0)+IF(W34=AP5,U33,0)+IF(AC34=AP5,AA33,0)+IF(E41=AP5,C40,0)+IF(K41=AP5,I40,0)+IF(Q41=AP5,O40,0)+IF(W41=AP5,U40,0)+IF(AC41=AP5,AA40,0) -> 0 | AU5: =IF(E50=AP5,C49,0)+IF(K50=AP5,I49,0)+IF(Q50=AP5,O49,0)++IF(W50=AP5,U49,0)+IF(AC50=AP5,AA49,0)+IF(E57=AP5,C56,0)+IF(K57=AP5,I56,0)+IF(Q57=AP5,O56,0)+IF(W57=AP5,U56,0)+IF(AC57=AP5,AA56,0)+IF(E64=AP5,C63,0)+IF(K64=AP5,I63,0)+IF(Q64=AP5,O63,0)+IF(W64=AP5,U63,0)+IF(AC64=AP5,AA63,0) -> 0 | AW5: =IF(E73=AP5,C72,0)+IF(K73=AP5,I72,0)+IF(Q73=AP5,O72,0)++IF(W73=AP5,U72,0)+IF(AC73=AP5,AA72,0)+IF(E80=AP5,C79,0)+IF(K80=AP5,I79,0)+IF(Q80=AP5,O79,0)+IF(W80=AP5,U79,0)+IF(AC80=AP5,AA79,0)+IF(E87=AP5,C86,0)+IF(K87=AP5,I86,0)+IF(Q87=AP5,O86,0)+IF(W87=AP5,U86,0)+IF(AC87=AP5,AA86,0) -> 0
B6: 账期 ： | C6: =IF(C4>0,RANDBETWEEN(2,4),0) -> 4 | D6: 季 | H6: 账期 ： | I6: =IF(I4>0,RANDBETWEEN(2,4),0) -> 4 | J6: 季 | N6: 账期 ： | O6: =IF(O4>0,RANDBETWEEN(2,4),0) -> 2 | P6: 季 | T6: 账期 ： | U6: =IF(U4>0,RANDBETWEEN(2,4),0) -> 3 | V6: 季 | Z6: 账期 ： | AA6: =IF(AA4>0,RANDBETWEEN(2,4),0) -> 2 | AB6: 季 | AG6: 4组 | AK6: 4组 | AL6: =AQ6+AS6+AU6+AW6 -> 0 | AM6: =AR6+AT6+AV6+AX6 -> 0 | AP6: 4 | AQ6: =IF(E4=AP6,C3,0)+IF(K4=AP6,I3,0)+IF(Q4=AP6,O3,0)++IF(W4=AP6,U3,0)+IF(AC4=AP6,AA3,0)+IF(E11=AP6,C10,0)+IF(K11=AP6,I10,0)+IF(Q11=AP6,O10,0)+IF(W11=AP6,U10,0)+IF(AC11=AP6,AA10,0)+IF(E18=AP6,C17,0)+IF(K18=AP6,I17,0)+IF(Q18=AP6,O17,0)+IF(W18=AP6,U17,0)+IF(AC18=AP6,AA17,0) -> 0 | AS6: =IF(E27=AP6,C26,0)+IF(K27=AP6,I26,0)+IF(Q27=AP6,O26,0)++IF(W27=AP6,U26,0)+IF(AC27=AP6,AA26,0)+IF(E34=AP6,C33,0)+IF(K34=AP6,I33,0)+IF(Q34=AP6,O33,0)+IF(W34=AP6,U33,0)+IF(AC34=AP6,AA33,0)+IF(E41=AP6,C40,0)+IF(K41=AP6,I40,0)+IF(Q41=AP6,O40,0)+IF(W41=AP6,U40,0)+IF(AC41=AP6,AA40,0) -> 0 | AU6: =IF(E50=AP6,C49,0)+IF(K50=AP6,I49,0)+IF(Q50=AP6,O49,0)++IF(W50=AP6,U49,0)+IF(AC50=AP6,AA49,0)+IF(E57=AP6,C56,0)+IF(K57=AP6,I56,0)+IF(Q57=AP6,O56,0)+IF(W57=AP6,U56,0)+IF(AC57=AP6,AA56,0)+IF(E64=AP6,C63,0)+IF(K64=AP6,I63,0)+IF(Q64=AP6,O63,0)+IF(W64=AP6,U63,0)+IF(AC64=AP6,AA63,0) -> 0 | AW6: =IF(E73=AP6,C72,0)+IF(K73=AP6,I72,0)+IF(Q73=AP6,O72,0)++IF(W73=AP6,U72,0)+IF(AC73=AP6,AA72,0)+IF(E80=AP6,C79,0)+IF(K80=AP6,I79,0)+IF(Q80=AP6,O79,0)+IF(W80=AP6,U79,0)+IF(AC80=AP6,AA79,0)+IF(E87=AP6,C86,0)+IF(K87=AP6,I86,0)+IF(Q87=AP6,O86,0)+IF(W87=AP6,U86,0)+IF(AC87=AP6,AA86,0) -> 0
B7: 01本地市场 | H7: 01本地市场 | N7: 01本地市场 | T7: 01本地市场 | Z7: 01本地市场 | AG7: 5组 | AK7: 5组 | AL7: =AQ7+AS7+AU7+AW7 -> 0 | AM7: =AR7+AT7+AV7+AX7 -> 0 | AP7: 5 | AQ7: =IF(E4=AP7,C3,0)+IF(K4=AP7,I3,0)+IF(Q4=AP7,O3,0)++IF(W4=AP7,U3,0)+IF(AC4=AP7,AA3,0)+IF(E11=AP7,C10,0)+IF(K11=AP7,I10,0)+IF(Q11=AP7,O10,0)+IF(W11=AP7,U10,0)+IF(AC11=AP7,AA10,0)+IF(E18=AP7,C17,0)+IF(K18=AP7,I17,0)+IF(Q18=AP7,O17,0)+IF(W18=AP7,U17,0)+IF(AC18=AP7,AA17,0) -> 0 | AS7: =IF(E27=AP7,C26,0)+IF(K27=AP7,I26,0)+IF(Q27=AP7,O26,0)++IF(W27=AP7,U26,0)+IF(AC27=AP7,AA26,0)+IF(E34=AP7,C33,0)+IF(K34=AP7,I33,0)+IF(Q34=AP7,O33,0)+IF(W34=AP7,U33,0)+IF(AC34=AP7,AA33,0)+IF(E41=AP7,C40,0)+IF(K41=AP7,I40,0)+IF(Q41=AP7,O40,0)+IF(W41=AP7,U40,0)+IF(AC41=AP7,AA40,0) -> 0 | AU7: =IF(E50=AP7,C49,0)+IF(K50=AP7,I49,0)+IF(Q50=AP7,O49,0)++IF(W50=AP7,U49,0)+IF(AC50=AP7,AA49,0)+IF(E57=AP7,C56,0)+IF(K57=AP7,I56,0)+IF(Q57=AP7,O56,0)+IF(W57=AP7,U56,0)+IF(AC57=AP7,AA56,0)+IF(E64=AP7,C63,0)+IF(K64=AP7,I63,0)+IF(Q64=AP7,O63,0)+IF(W64=AP7,U63,0)+IF(AC64=AP7,AA63,0) -> 0 | AW7: =IF(E73=AP7,C72,0)+IF(K73=AP7,I72,0)+IF(Q73=AP7,O72,0)++IF(W73=AP7,U72,0)+IF(AC73=AP7,AA72,0)+IF(E80=AP7,C79,0)+IF(K80=AP7,I79,0)+IF(Q80=AP7,O79,0)+IF(W80=AP7,U79,0)+IF(AC80=AP7,AA79,0)+IF(E87=AP7,C86,0)+IF(K87=AP7,I86,0)+IF(Q87=AP7,O86,0)+IF(W87=AP7,U86,0)+IF(AC87=AP7,AA86,0) -> 0
AG8: 6组 | AK8: 6组 | AL8: =AQ8+AS8+AU8+AW8 -> 0 | AM8: =AR8+AT8+AV8+AX8 -> 0 | AP8: 6 | AQ8: =IF(E4=AP8,C3,0)+IF(K4=AP8,I3,0)+IF(Q4=AP8,O3,0)++IF(W4=AP8,U3,0)+IF(AC4=AP8,AA3,0)+IF(E11=AP8,C10,0)+IF(K11=AP8,I10,0)+IF(Q11=AP8,O10,0)+IF(W11=AP8,U10,0)+IF(AC11=AP8,AA10,0)+IF(E18=AP8,C17,0)+IF(K18=AP8,I17,0)+IF(Q18=AP8,O17,0)+IF(W18=AP8,U17,0)+IF(AC18=AP8,AA17,0) -> 0 | AS8: =IF(E27=AP8,C26,0)+IF(K27=AP8,I26,0)+IF(Q27=AP8,O26,0)++IF(W27=AP8,U26,0)+IF(AC27=AP8,AA26,0)+IF(E34=AP8,C33,0)+IF(K34=AP8,I33,0)+IF(Q34=AP8,O33,0)+IF(W34=AP8,U33,0)+IF(AC34=AP8,AA33,0)+IF(E41=AP8,C40,0)+IF(K41=AP8,I40,0)+IF(Q41=AP8,O40,0)+IF(W41=AP8,U40,0)+IF(AC41=AP8,AA40,0) -> 0 | AU8: =IF(E50=AP8,C49,0)+IF(K50=AP8,I49,0)+IF(Q50=AP8,O49,0)++IF(W50=AP8,U49,0)+IF(AC50=AP8,AA49,0)+IF(E57=AP8,C56,0)+IF(K57=AP8,I56,0)+IF(Q57=AP8,O56,0)+IF(W57=AP8,U56,0)+IF(AC57=AP8,AA56,0)+IF(E64=AP8,C63,0)+IF(K64=AP8,I63,0)+IF(Q64=AP8,O63,0)+IF(W64=AP8,U63,0)+IF(AC64=AP8,AA63,0) -> 0 | AW8: =IF(E73=AP8,C72,0)+IF(K73=AP8,I72,0)+IF(Q73=AP8,O72,0)++IF(W73=AP8,U72,0)+IF(AC73=AP8,AA72,0)+IF(E80=AP8,C79,0)+IF(K80=AP8,I79,0)+IF(Q80=AP8,O79,0)+IF(W80=AP8,U79,0)+IF(AC80=AP8,AA79,0)+IF(E87=AP8,C86,0)+IF(K87=AP8,I86,0)+IF(Q87=AP8,O86,0)+IF(W87=AP8,U86,0)+IF(AC87=AP8,AA86,0) -> 0
B9: 代办过检 | H9: 代办过检 | N9: 代办过检 | T9: 代办过检 | Z9: 代办过检 | AG9: 7组 | AK9: 7组 | AL9: =AQ9+AS9+AU9+AW9 -> 0 | AM9: =AR9+AT9+AV9+AX9 -> 0 | AP9: 7 | AQ9: =IF(E4=AP9,C3,0)+IF(K4=AP9,I3,0)+IF(Q4=AP9,O3,0)++IF(W4=AP9,U3,0)+IF(AC4=AP9,AA3,0)+IF(E11=AP9,C10,0)+IF(K11=AP9,I10,0)+IF(Q11=AP9,O10,0)+IF(W11=AP9,U10,0)+IF(AC11=AP9,AA10,0)+IF(E18=AP9,C17,0)+IF(K18=AP9,I17,0)+IF(Q18=AP9,O17,0)+IF(W18=AP9,U17,0)+IF(AC18=AP9,AA17,0) -> 0 | AS9: =IF(E27=AP9,C26,0)+IF(K27=AP9,I26,0)+IF(Q27=AP9,O26,0)++IF(W27=AP9,U26,0)+IF(AC27=AP9,AA26,0)+IF(E34=AP9,C33,0)+IF(K34=AP9,I33,0)+IF(Q34=AP9,O33,0)+IF(W34=AP9,U33,0)+IF(AC34=AP9,AA33,0)+IF(E41=AP9,C40,0)+IF(K41=AP9,I40,0)+IF(Q41=AP9,O40,0)+IF(W41=AP9,U40,0)+IF(AC41=AP9,AA40,0) -> 0 | AU9: =IF(E50=AP9,C49,0)+IF(K50=AP9,I49,0)+IF(Q50=AP9,O49,0)++IF(W50=AP9,U49,0)+IF(AC50=AP9,AA49,0)+IF(E57=AP9,C56,0)+IF(K57=AP9,I56,0)+IF(Q57=AP9,O56,0)+IF(W57=AP9,U56,0)+IF(AC57=AP9,AA56,0)+IF(E64=AP9,C63,0)+IF(K64=AP9,I63,0)+IF(Q64=AP9,O63,0)+IF(W64=AP9,U63,0)+IF(AC64=AP9,AA63,0) -> 0 | AW9: =IF(E73=AP9,C72,0)+IF(K73=AP9,I72,0)+IF(Q73=AP9,O72,0)++IF(W73=AP9,U72,0)+IF(AC73=AP9,AA72,0)+IF(E80=AP9,C79,0)+IF(K80=AP9,I79,0)+IF(Q80=AP9,O79,0)+IF(W80=AP9,U79,0)+IF(AC80=AP9,AA79,0)+IF(E87=AP9,C86,0)+IF(K87=AP9,I86,0)+IF(Q87=AP9,O86,0)+IF(W87=AP9,U86,0)+IF(AC87=AP9,AA86,0) -> 0
B10: 总额 ： | C10: =IF(C11>0,J22*C11-P22*(C11-((D23+J23)/2)),0) -> 19 | D10: M | H10: 总额 ： | I10: =IF(I11>0,J22*I11-P22*(I11-((D23+J23)/2)),0) -> 15 | J10: M | N10: 总额 ： | O10: =IF(O11>0,J22*O11-P22*(O11-((D23+J23)/2)),0) -> 19 | P10: M | T10: 总额 ： | U10: =IF(U11>0,J22*U11-P22*(U11-((D23+J23)/2)),0) -> 11 | V10: M | Z10: 总额 ： | AA10: =IF(AA11>0,J22*AA11-P22*(AA11-((D23+J23)/2)),0) -> 19 | AB10: M | AG10: 8组 | AK10: 8组 | AL10: =AQ10+AS10+AU10+AW10 -> 0 | AM10: =AR10+AT10+AV10+AX10 -> 0 | AP10: 8 | AQ10: =IF(E4=AP10,C3,0)+IF(K4=AP10,I3,0)+IF(Q4=AP10,O3,0)++IF(W4=AP10,U3,0)+IF(AC4=AP10,AA3,0)+IF(E11=AP10,C10,0)+IF(K11=AP10,I10,0)+IF(Q11=AP10,O10,0)+IF(W11=AP10,U10,0)+IF(AC11=AP10,AA10,0)+IF(E18=AP10,C17,0)+IF(K18=AP10,I17,0)+IF(Q18=AP10,O17,0)+IF(W18=AP10,U17,0)+IF(AC18=AP10,AA17,0) -> 0 | AS10: =IF(E27=AP10,C26,0)+IF(K27=AP10,I26,0)+IF(Q27=AP10,O26,0)++IF(W27=AP10,U26,0)+IF(AC27=AP10,AA26,0)+IF(E34=AP10,C33,0)+IF(K34=AP10,I33,0)+IF(Q34=AP10,O33,0)+IF(W34=AP10,U33,0)+IF(AC34=AP10,AA33,0)+IF(E41=AP10,C40,0)+IF(K41=AP10,I40,0)+IF(Q41=AP10,O40,0)+IF(W41=AP10,U40,0)+IF(AC41=AP10,AA40,0) -> 0 | AU10: =IF(E50=AP10,C49,0)+IF(K50=AP10,I49,0)+IF(Q50=AP10,O49,0)++IF(W50=AP10,U49,0)+IF(AC50=AP10,AA49,0)+IF(E57=AP10,C56,0)+IF(K57=AP10,I56,0)+IF(Q57=AP10,O56,0)+IF(W57=AP10,U56,0)+IF(AC57=AP10,AA56,0)+IF(E64=AP10,C63,0)+IF(K64=AP10,I63,0)+IF(Q64=AP10,O63,0)+IF(W64=AP10,U63,0)+IF(AC64=AP10,AA63,0) -> 0 | AW10: =IF(E73=AP10,C72,0)+IF(K73=AP10,I72,0)+IF(Q73=AP10,O72,0)++IF(W73=AP10,U72,0)+IF(AC73=AP10,AA72,0)+IF(E80=AP10,C79,0)+IF(K80=AP10,I79,0)+IF(Q80=AP10,O79,0)+IF(W80=AP10,U79,0)+IF(AC80=AP10,AA79,0)+IF(E87=AP10,C86,0)+IF(K87=AP10,I86,0)+IF(Q87=AP10,O86,0)+IF(W87=AP10,U86,0)+IF(AC87=AP10,AA86,0) -> 0
B11: 数量 ： | C11: =IF(D22>=6,RANDBETWEEN(D23,J23),0) -> 4 | F11: 第一年：区域市场处于启动期，代检、两舱、贵宾、定制四类产品均未形成有效销量，以市场调研、渠道搭建、品牌渗透为核心工作，为后续产品落地做足准备。 第二年：代办过检率先实现规模化突破，成为区域市场的核心增长引擎；两舱贵宾同步放量，规模仅次于代办过检；贵宾、会员定制完成试点布局，实现从 0 到 1 的销量突破，完成区域市场的产品矩阵搭建，快速抢占区域份额。 第三年：代办过检销量较第二年小幅回落，但仍保持市场主力地位；两舱贵宾规模稳步增长，商务贵宾持续放量；会员定制实现跨越式增长，销量反超商务贵宾，成为区域市场新的增长极，形成 “代办过检铺规模、会员定制提价值” 的良性结构，完成区域市场的深度渗透与品牌占位。 | H11: 数量 ： | I11: =IF(D22>=7,RANDBETWEEN(D23,J23),0) -> 3 | N11: 数量 ： | O11: =IF(D22>=8,RANDBETWEEN(D23,J23),0) -> 4 | T11: 数量 ： | U11: =IF(D22>=9,RANDBETWEEN(D23,J23),0) -> 2 | Z11: 数量 ： | AA11: =IF(D22>=10,RANDBETWEEN(D23,J23),0) -> 4 | AG11: 9组 | AK11: 9组 | AL11: =AQ11+AS11+AU11+AW11 -> 0 | AM11: =AR11+AT11+AV11+AX11 -> 0 | AP11: 9 | AQ11: =IF(E4=AP11,C3,0)+IF(K4=AP11,I3,0)+IF(Q4=AP11,O3,0)++IF(W4=AP11,U3,0)+IF(AC4=AP11,AA3,0)+IF(E11=AP11,C10,0)+IF(K11=AP11,I10,0)+IF(Q11=AP11,O10,0)+IF(W11=AP11,U10,0)+IF(AC11=AP11,AA10,0)+IF(E18=AP11,C17,0)+IF(K18=AP11,I17,0)+IF(Q18=AP11,O17,0)+IF(W18=AP11,U17,0)+IF(AC18=AP11,AA17,0) -> 0 | AS11: =IF(E27=AP11,C26,0)+IF(K27=AP11,I26,0)+IF(Q27=AP11,O26,0)++IF(W27=AP11,U26,0)+IF(AC27=AP11,AA26,0)+IF(E34=AP11,C33,0)+IF(K34=AP11,I33,0)+IF(Q34=AP11,O33,0)+IF(W34=AP11,U33,0)+IF(AC34=AP11,AA33,0)+IF(E41=AP11,C40,0)+IF(K41=AP11,I40,0)+IF(Q41=AP11,O40,0)+IF(W41=AP11,U40,0)+IF(AC41=AP11,AA40,0) -> 0 | AU11: =IF(E50=AP11,C49,0)+IF(K50=AP11,I49,0)+IF(Q50=AP11,O49,0)++IF(W50=AP11,U49,0)+IF(AC50=AP11,AA49,0)+IF(E57=AP11,C56,0)+IF(K57=AP11,I56,0)+IF(Q57=AP11,O56,0)+IF(W57=AP11,U56,0)+IF(AC57=AP11,AA56,0)+IF(E64=AP11,C63,0)+IF(K64=AP11,I63,0)+IF(Q64=AP11,O63,0)+IF(W64=AP11,U63,0)+IF(AC64=AP11,AA63,0) -> 0 | AW11: =IF(E73=AP11,C72,0)+IF(K73=AP11,I72,0)+IF(Q73=AP11,O72,0)++IF(W73=AP11,U72,0)+IF(AC73=AP11,AA72,0)+IF(E80=AP11,C79,0)+IF(K80=AP11,I79,0)+IF(Q80=AP11,O79,0)+IF(W80=AP11,U79,0)+IF(AC80=AP11,AA79,0)+IF(E87=AP11,C86,0)+IF(K87=AP11,I86,0)+IF(Q87=AP11,O86,0)+IF(W87=AP11,U86,0)+IF(AC87=AP11,AA86,0) -> 0
B12: 单价 ： | C12: =C10/C11 -> 4.75 | D12: M | H12: 单价 ： | I12: =I10/I11 -> 5 | J12: M | N12: 单价 ： | O12: =O10/O11 -> 4.75 | P12: M | T12: 单价 ： | U12: =U10/U11 -> 5.5 | V12: M | Z12: 单价 ： | AA12: =AA10/AA11 -> 4.75 | AB12: M | AG12: 10组 | AK12: 10组 | AL12: =AQ12+AS12+AU12+AW12 -> 0 | AM12: =AR12+AT12+AV12+AX12 -> 0 | AP12: 10 | AQ12: =IF(E4=AP12,C3,0)+IF(K4=AP12,I3,0)+IF(Q4=AP12,O3,0)++IF(W4=AP12,U3,0)+IF(AC4=AP12,AA3,0)+IF(E11=AP12,C10,0)+IF(K11=AP12,I10,0)+IF(Q11=AP12,O10,0)+IF(W11=AP12,U10,0)+IF(AC11=AP12,AA10,0)+IF(E18=AP12,C17,0)+IF(K18=AP12,I17,0)+IF(Q18=AP12,O17,0)+IF(W18=AP12,U17,0)+IF(AC18=AP12,AA17,0) -> 0 | AS12: =IF(E27=AP12,C26,0)+IF(K27=AP12,I26,0)+IF(Q27=AP12,O26,0)++IF(W27=AP12,U26,0)+IF(AC27=AP12,AA26,0)+IF(E34=AP12,C33,0)+IF(K34=AP12,I33,0)+IF(Q34=AP12,O33,0)+IF(W34=AP12,U33,0)+IF(AC34=AP12,AA33,0)+IF(E41=AP12,C40,0)+IF(K41=AP12,I40,0)+IF(Q41=AP12,O40,0)+IF(W41=AP12,U40,0)+IF(AC41=AP12,AA40,0) -> 0 | AU12: =IF(E50=AP12,C49,0)+IF(K50=AP12,I49,0)+IF(Q50=AP12,O49,0)++IF(W50=AP12,U49,0)+IF(AC50=AP12,AA49,0)+IF(E57=AP12,C56,0)+IF(K57=AP12,I56,0)+IF(Q57=AP12,O56,0)+IF(W57=AP12,U56,0)+IF(AC57=AP12,AA56,0)+IF(E64=AP12,C63,0)+IF(K64=AP12,I63,0)+IF(Q64=AP12,O63,0)+IF(W64=AP12,U63,0)+IF(AC64=AP12,AA63,0) -> 0 | AW12: =IF(E73=AP12,C72,0)+IF(K73=AP12,I72,0)+IF(Q73=AP12,O72,0)++IF(W73=AP12,U72,0)+IF(AC73=AP12,AA72,0)+IF(E80=AP12,C79,0)+IF(K80=AP12,I79,0)+IF(Q80=AP12,O79,0)+IF(W80=AP12,U79,0)+IF(AC80=AP12,AA79,0)+IF(E87=AP12,C86,0)+IF(K87=AP12,I86,0)+IF(Q87=AP12,O86,0)+IF(W87=AP12,U86,0)+IF(AC87=AP12,AA86,0) -> 0
B13: 账期 ： | C13: =IF(C11>0,RANDBETWEEN(2,4),0) -> 4 | D13: 季 | H13: 账期 ： | I13: =IF(I11>0,RANDBETWEEN(2,4),0) -> 3 | J13: 季 | N13: 账期 ： | O13: =IF(O11>0,RANDBETWEEN(2,4),0) -> 4 | P13: 季 | T13: 账期 ： | U13: =IF(U11>0,RANDBETWEEN(2,4),0) -> 3 | V13: 季 | Z13: 账期 ： | AA13: =IF(AA11>0,RANDBETWEEN(2,4),0) -> 2 | AB13: 季 | AG13: 11组 | AK13: 11组 | AL13: =AQ13+AS13+AU13+AW13 -> 0 | AM13: =AR13+AT13+AV13+AX13 -> 0 | AP13: 11 | AQ13: =IF(E4=AP13,C3,0)+IF(K4=AP13,I3,0)+IF(Q4=AP13,O3,0)++IF(W4=AP13,U3,0)+IF(AC4=AP13,AA3,0)+IF(E11=AP13,C10,0)+IF(K11=AP13,I10,0)+IF(Q11=AP13,O10,0)+IF(W11=AP13,U10,0)+IF(AC11=AP13,AA10,0)+IF(E18=AP13,C17,0)+IF(K18=AP13,I17,0)+IF(Q18=AP13,O17,0)+IF(W18=AP13,U17,0)+IF(AC18=AP13,AA17,0) -> 0 | AS13: =IF(E27=AP13,C26,0)+IF(K27=AP13,I26,0)+IF(Q27=AP13,O26,0)++IF(W27=AP13,U26,0)+IF(AC27=AP13,AA26,0)+IF(E34=AP13,C33,0)+IF(K34=AP13,I33,0)+IF(Q34=AP13,O33,0)+IF(W34=AP13,U33,0)+IF(AC34=AP13,AA33,0)+IF(E41=AP13,C40,0)+IF(K41=AP13,I40,0)+IF(Q41=AP13,O40,0)+IF(W41=AP13,U40,0)+IF(AC41=AP13,AA40,0) -> 0 | AU13: =IF(E50=AP13,C49,0)+IF(K50=AP13,I49,0)+IF(Q50=AP13,O49,0)++IF(W50=AP13,U49,0)+IF(AC50=AP13,AA49,0)+IF(E57=AP13,C56,0)+IF(K57=AP13,I56,0)+IF(Q57=AP13,O56,0)+IF(W57=AP13,U56,0)+IF(AC57=AP13,AA56,0)+IF(E64=AP13,C63,0)+IF(K64=AP13,I63,0)+IF(Q64=AP13,O63,0)+IF(W64=AP13,U63,0)+IF(AC64=AP13,AA63,0) -> 0 | AW13: =IF(E73=AP13,C72,0)+IF(K73=AP13,I72,0)+IF(Q73=AP13,O72,0)++IF(W73=AP13,U72,0)+IF(AC73=AP13,AA72,0)+IF(E80=AP13,C79,0)+IF(K80=AP13,I79,0)+IF(Q80=AP13,O79,0)+IF(W80=AP13,U79,0)+IF(AC80=AP13,AA79,0)+IF(E87=AP13,C86,0)+IF(K87=AP13,I86,0)+IF(Q87=AP13,O86,0)+IF(W87=AP13,U86,0)+IF(AC87=AP13,AA86,0) -> 0
B14: 01本地市场 | H14: 01本地市场 | N14: 01本地市场 | T14: 01本地市场 | Z14: 01本地市场 | AG14: 12组 | AK14: 12组 | AL14: =AQ14+AS14+AU14+AW14 -> 0 | AM14: =AR14+AT14+AV14+AX14 -> 0 | AP14: 12 | AQ14: =IF(E4=AP14,C3,0)+IF(K4=AP14,I3,0)+IF(Q4=AP14,O3,0)++IF(W4=AP14,U3,0)+IF(AC4=AP14,AA3,0)+IF(E11=AP14,C10,0)+IF(K11=AP14,I10,0)+IF(Q11=AP14,O10,0)+IF(W11=AP14,U10,0)+IF(AC11=AP14,AA10,0)+IF(E18=AP14,C17,0)+IF(K18=AP14,I17,0)+IF(Q18=AP14,O17,0)+IF(W18=AP14,U17,0)+IF(AC18=AP14,AA17,0) -> 0 | AS14: =IF(E27=AP14,C26,0)+IF(K27=AP14,I26,0)+IF(Q27=AP14,O26,0)++IF(W27=AP14,U26,0)+IF(AC27=AP14,AA26,0)+IF(E34=AP14,C33,0)+IF(K34=AP14,I33,0)+IF(Q34=AP14,O33,0)+IF(W34=AP14,U33,0)+IF(AC34=AP14,AA33,0)+IF(E41=AP14,C40,0)+IF(K41=AP14,I40,0)+IF(Q41=AP14,O40,0)+IF(W41=AP14,U40,0)+IF(AC41=AP14,AA40,0) -> 0 | AU14: =IF(E50=AP14,C49,0)+IF(K50=AP14,I49,0)+IF(Q50=AP14,O49,0)++IF(W50=AP14,U49,0)+IF(AC50=AP14,AA49,0)+IF(E57=AP14,C56,0)+IF(K57=AP14,I56,0)+IF(Q57=AP14,O56,0)+IF(W57=AP14,U56,0)+IF(AC57=AP14,AA56,0)+IF(E64=AP14,C63,0)+IF(K64=AP14,I63,0)+IF(Q64=AP14,O63,0)+IF(W64=AP14,U63,0)+IF(AC64=AP14,AA63,0) -> 0 | AW14: =IF(E73=AP14,C72,0)+IF(K73=AP14,I72,0)+IF(Q73=AP14,O72,0)++IF(W73=AP14,U72,0)+IF(AC73=AP14,AA72,0)+IF(E80=AP14,C79,0)+IF(K80=AP14,I79,0)+IF(Q80=AP14,O79,0)+IF(W80=AP14,U79,0)+IF(AC80=AP14,AA79,0)+IF(E87=AP14,C86,0)+IF(K87=AP14,I86,0)+IF(Q87=AP14,O86,0)+IF(W87=AP14,U86,0)+IF(AC87=AP14,AA86,0) -> 0
AG15: 13组 | AK15: 13组 | AL15: =AQ15+AS15+AU15+AW15 -> 0 | AM15: =AR15+AT15+AV15+AX15 -> 0 | AP15: 13 | AQ15: =IF(E4=AP15,C3,0)+IF(K4=AP15,I3,0)+IF(Q4=AP15,O3,0)++IF(W4=AP15,U3,0)+IF(AC4=AP15,AA3,0)+IF(E11=AP15,C10,0)+IF(K11=AP15,I10,0)+IF(Q11=AP15,O10,0)+IF(W11=AP15,U10,0)+IF(AC11=AP15,AA10,0)+IF(E18=AP15,C17,0)+IF(K18=AP15,I17,0)+IF(Q18=AP15,O17,0)+IF(W18=AP15,U17,0)+IF(AC18=AP15,AA17,0) -> 0 | AS15: =IF(E27=AP15,C26,0)+IF(K27=AP15,I26,0)+IF(Q27=AP15,O26,0)++IF(W27=AP15,U26,0)+IF(AC27=AP15,AA26,0)+IF(E34=AP15,C33,0)+IF(K34=AP15,I33,0)+IF(Q34=AP15,O33,0)+IF(W34=AP15,U33,0)+IF(AC34=AP15,AA33,0)+IF(E41=AP15,C40,0)+IF(K41=AP15,I40,0)+IF(Q41=AP15,O40,0)+IF(W41=AP15,U40,0)+IF(AC41=AP15,AA40,0) -> 0 | AU15: =IF(E50=AP15,C49,0)+IF(K50=AP15,I49,0)+IF(Q50=AP15,O49,0)++IF(W50=AP15,U49,0)+IF(AC50=AP15,AA49,0)+IF(E57=AP15,C56,0)+IF(K57=AP15,I56,0)+IF(Q57=AP15,O56,0)+IF(W57=AP15,U56,0)+IF(AC57=AP15,AA56,0)+IF(E64=AP15,C63,0)+IF(K64=AP15,I63,0)+IF(Q64=AP15,O63,0)+IF(W64=AP15,U63,0)+IF(AC64=AP15,AA63,0) -> 0 | AW15: =IF(E73=AP15,C72,0)+IF(K73=AP15,I72,0)+IF(Q73=AP15,O72,0)++IF(W73=AP15,U72,0)+IF(AC73=AP15,AA72,0)+IF(E80=AP15,C79,0)+IF(K80=AP15,I79,0)+IF(Q80=AP15,O79,0)+IF(W80=AP15,U79,0)+IF(AC80=AP15,AA79,0)+IF(E87=AP15,C86,0)+IF(K87=AP15,I86,0)+IF(Q87=AP15,O86,0)+IF(W87=AP15,U86,0)+IF(AC87=AP15,AA86,0) -> 0
B16: 代办过检 | H16: 代办过检 | N16: 代办过检 | T16: 代办过检 | Z16: 代办过检 | AG16: 14组 | AK16: 14组 | AL16: =AQ16+AS16+AU16+AW16 -> 0 | AM16: =AR16+AT16+AV16+AX16 -> 0 | AP16: 14 | AQ16: =IF(E4=AP16,C3,0)+IF(K4=AP16,I3,0)+IF(Q4=AP16,O3,0)++IF(W4=AP16,U3,0)+IF(AC4=AP16,AA3,0)+IF(E11=AP16,C10,0)+IF(K11=AP16,I10,0)+IF(Q11=AP16,O10,0)+IF(W11=AP16,U10,0)+IF(AC11=AP16,AA10,0)+IF(E18=AP16,C17,0)+IF(K18=AP16,I17,0)+IF(Q18=AP16,O17,0)+IF(W18=AP16,U17,0)+IF(AC18=AP16,AA17,0) -> 0 | AS16: =IF(E27=AP16,C26,0)+IF(K27=AP16,I26,0)+IF(Q27=AP16,O26,0)++IF(W27=AP16,U26,0)+IF(AC27=AP16,AA26,0)+IF(E34=AP16,C33,0)+IF(K34=AP16,I33,0)+IF(Q34=AP16,O33,0)+IF(W34=AP16,U33,0)+IF(AC34=AP16,AA33,0)+IF(E41=AP16,C40,0)+IF(K41=AP16,I40,0)+IF(Q41=AP16,O40,0)+IF(W41=AP16,U40,0)+IF(AC41=AP16,AA40,0) -> 0 | AU16: =IF(E50=AP16,C49,0)+IF(K50=AP16,I49,0)+IF(Q50=AP16,O49,0)++IF(W50=AP16,U49,0)+IF(AC50=AP16,AA49,0)+IF(E57=AP16,C56,0)+IF(K57=AP16,I56,0)+IF(Q57=AP16,O56,0)+IF(W57=AP16,U56,0)+IF(AC57=AP16,AA56,0)+IF(E64=AP16,C63,0)+IF(K64=AP16,I63,0)+IF(Q64=AP16,O63,0)+IF(W64=AP16,U63,0)+IF(AC64=AP16,AA63,0) -> 0 | AW16: =IF(E73=AP16,C72,0)+IF(K73=AP16,I72,0)+IF(Q73=AP16,O72,0)++IF(W73=AP16,U72,0)+IF(AC73=AP16,AA72,0)+IF(E80=AP16,C79,0)+IF(K80=AP16,I79,0)+IF(Q80=AP16,O79,0)+IF(W80=AP16,U79,0)+IF(AC80=AP16,AA79,0)+IF(E87=AP16,C86,0)+IF(K87=AP16,I86,0)+IF(Q87=AP16,O86,0)+IF(W87=AP16,U86,0)+IF(AC87=AP16,AA86,0) -> 0
B17: 总额 ： | C17: =IF(C18>0,J22*C18-P22*(C18-((D23+J23)/2)),0) -> 19 | D17: M | H17: 总额 ： | I17: =IF(I18>0,J22*I18-P22*(I18-((D23+J23)/2)),0) -> 0 | J17: M | N17: 总额 ： | O17: =IF(O18>0,J22*O18-P22*(O18-((D23+J23)/2)),0) -> 0 | P17: M | T17: 总额 ： | U17: =IF(U18>0,J22*U18-P22*(U18-((D23+J23)/2)),0) -> 0 | V17: M | Z17: 总额 ： | AA17: =IF(AA18>0,J22*AA18-P22*(AA18-((D23+J23)/2)),0) -> 0 | AB17: M | AG17: 15组 | AK17: 15组 | AL17: =AQ17+AS17+AU17+AW17 -> 0 | AM17: =AR17+AT17+AV17+AX17 -> 0 | AP17: 15 | AQ17: =IF(E4=AP17,C3,0)+IF(K4=AP17,I3,0)+IF(Q4=AP17,O3,0)++IF(W4=AP17,U3,0)+IF(AC4=AP17,AA3,0)+IF(E11=AP17,C10,0)+IF(K11=AP17,I10,0)+IF(Q11=AP17,O10,0)+IF(W11=AP17,U10,0)+IF(AC11=AP17,AA10,0)+IF(E18=AP17,C17,0)+IF(K18=AP17,I17,0)+IF(Q18=AP17,O17,0)+IF(W18=AP17,U17,0)+IF(AC18=AP17,AA17,0) -> 0 | AS17: =IF(E27=AP17,C26,0)+IF(K27=AP17,I26,0)+IF(Q27=AP17,O26,0)++IF(W27=AP17,U26,0)+IF(AC27=AP17,AA26,0)+IF(E34=AP17,C33,0)+IF(K34=AP17,I33,0)+IF(Q34=AP17,O33,0)+IF(W34=AP17,U33,0)+IF(AC34=AP17,AA33,0)+IF(E41=AP17,C40,0)+IF(K41=AP17,I40,0)+IF(Q41=AP17,O40,0)+IF(W41=AP17,U40,0)+IF(AC41=AP17,AA40,0) -> 0 | AU17: =IF(E50=AP17,C49,0)+IF(K50=AP17,I49,0)+IF(Q50=AP17,O49,0)++IF(W50=AP17,U49,0)+IF(AC50=AP17,AA49,0)+IF(E57=AP17,C56,0)+IF(K57=AP17,I56,0)+IF(Q57=AP17,O56,0)+IF(W57=AP17,U56,0)+IF(AC57=AP17,AA56,0)+IF(E64=AP17,C63,0)+IF(K64=AP17,I63,0)+IF(Q64=AP17,O63,0)+IF(W64=AP17,U63,0)+IF(AC64=AP17,AA63,0) -> 0 | AW17: =IF(E73=AP17,C72,0)+IF(K73=AP17,I72,0)+IF(Q73=AP17,O72,0)++IF(W73=AP17,U72,0)+IF(AC73=AP17,AA72,0)+IF(E80=AP17,C79,0)+IF(K80=AP17,I79,0)+IF(Q80=AP17,O79,0)+IF(W80=AP17,U79,0)+IF(AC80=AP17,AA79,0)+IF(E87=AP17,C86,0)+IF(K87=AP17,I86,0)+IF(Q87=AP17,O86,0)+IF(W87=AP17,U86,0)+IF(AC87=AP17,AA86,0) -> 0
B18: 数量 ： | C18: =IF(D22>=11,RANDBETWEEN(D23,J23),0) -> 4 | H18: 数量 ： | I18: =IF(D22>=12,RANDBETWEEN(D23,J23),0) -> 0 | N18: 数量 ： | O18: =IF(D22>=13,RANDBETWEEN(D23,J23),0) -> 0 | T18: 数量 ： | U18: =IF(D22>=14,RANDBETWEEN(D23,J23),0) -> 0 | Z18: 数量 ： | AA18: =IF(D22>=15,RANDBETWEEN(D23,J23),0) -> 0
B19: 单价 ： | C19: =C17/C18 -> 4.75 | D19: M | F19: 第一年、第二年：全国市场处于筹备期，四类产品均未实现规模化销量，核心聚焦全国渠道网络搭建、两舱化体系建设、全国品牌推广，为第三年的全面爆发奠定代检。 第三年：全国市场实现全面起量，代办过检以绝对规模领跑，成为全国市场的核心销量支撑；两舱贵宾紧随其后，形成稳定的第二增长曲线；商务贵宾实现规模化落地，会员定制完成从 0 到 1 的突破，形成 “代办过检铺全国、高价值产品抢高端” 的全国化布局，快速建立行业级影响力。 | H19: 单价 ： | I19: =I17/I18 -> #DIV/0! | J19: M | N19: 单价 ： | O19: =O17/O18 -> #DIV/0! | P19: M | T19: 单价 ： | U19: =U17/U18 -> #DIV/0! | V19: M | Z19: 单价 ： | AA19: =AA17/AA18 -> #DIV/0! | AB19: M
B20: 账期 ： | C20: =IF(C18>0,RANDBETWEEN(2,4),0) -> 4 | D20: 季 | H20: 账期 ： | I20: =IF(I18>0,RANDBETWEEN(2,4),0) -> 0 | J20: 季 | N20: 账期 ： | O20: =IF(O18>0,RANDBETWEEN(2,4),0) -> 0 | P20: 季 | T20: 账期 ： | U20: =IF(U18>0,RANDBETWEEN(2,4),0) -> 0 | V20: 季 | Z20: 账期 ： | AA20: =IF(AA18>0,RANDBETWEEN(2,4),0) -> 0 | AB20: 季
B21: 01本地市场 | H21: 01本地市场 | N21: 01本地市场 | T21: 01本地市场 | Z21: 01本地市场
B22: 订单数量控制 | D22: =市场预测!L17 -> 11 | H22: 商品均价 | J22: 5 | N22: 波动系数（1-5） | P22: 1 | S22: 订单总数量 | V22: =C4+I4+O4+AA4+C11+U4+O11+U11+I11+AA11+AA18+U18+O18+I18+C18 -> 34
B23: 最小订单数量 | D23: 2 | H23: 最大订单数量 | J23: 4 | N23: 平均订单量 | P23: =V22/市场预测!O14 -> 4.25 | S23: 订单总金额 | V23: =C3+I3+O3+U3+AA3+C10+I10+O10+U10+AA10+C17+I17+O17+U17+AA17 -> 169
B25: 两舱贵宾 | H25: 两舱贵宾 | N25: 两舱贵宾 | T25: 两舱贵宾 | Z25: 两舱贵宾
B26: 总额 ： | C26: =IF(C27>0,J45*C27-P45*(C27-((D46+J46)/2)),0) -> 13 | D26: M | H26: 总额 ： | I26: =IF(I27>0,J45*I27-P45*(I27-((D46+J46)/2)),0) -> 0 | J26: M | N26: 总额 ： | O26: =IF(O27>0,J45*O27-P45*(O27-((D46+J46)/2)),0) -> 0 | P26: M | T26: 总额 ： | U26: =IF(U27>0,J45*U27-P45*(U27-((D46+J46)/2)),0) -> 0 | V26: M | Z26: 总额 ： | AA26: =IF(AA27>0,J45*AA27-P45*(AA27-((D46+J46)/2)),0) -> 0 | AB26: M
