Workbook

Sheet 初始年财报
B2: 损益表 | H2: 资产负债表
F3: 资产 | J3: 负 债 ＋ 权 益
B4: 销售收入 | C4: 32 | F4: 非流动资产 | J4: 负债
B5: 直接成本 | C5: 15 | F5: 在建生产线 | G5: 0
F6: 厂房 | G6: 40
B7: 毛利 | C7: =C4-C5 -> 17 | F7: 生产线残值 | G7: 3 | J7: 短期负债 | K7: 20
F8: 待折资产 | G8: 0 | J8: 长期负债 | K8: 0
F9: 总固定资产 | G9: =G6+G7+G8 -> 43
B10: 综合费用 | C10: 13 | J10: 总负债 | K10: =K6+K7+K8 -> 20
B11: 折旧 | C11: 1 | F11: 流动资产
B13: 营业利润 | C13: =C7-C10-C11 -> 3 | F13: 现金 | G13: 36 | H13: 手动输入 | J13: 总权益
F14: 应收款 | G14: 0 | H14: 手动输入
F15: 在制品 | G15: 6 | H15: 手动输入 | J15: 股东资本 | K15: 50
B16: 财务收入/支出 | C16: 2 | F16: 成品 | G16: 4 | H16: 手动输入 | J16: 利润留存 | K16: 17
B17: 额外收入/支出 | C17: 2 | F17: 材料 | G17: 1 | H17: 手动输入 | J17: 年度净利润 | K17: =C22 -> 2
F18: 所得税后现金 | G18: =G13-C21 -> 35
B19: 税前利润 | C19: =C13-C16+C17 -> 3 | F19: 总流动资产 | G19: =SUM(G14:G18) -> 46 | J19: 总股东权益 | K19: =K15+K16+K17 -> 69
B21: 所得税 | C21: 1 | D21: 手动输入
B22: 年度净利润 | C22: =C19-C21 -> 2 | F22: 总资产 | G22: =G9+G19 -> 89 | J22: 总负债权益 | K22: =K19+K10 -> 89

Sheet 0年经营
A1: 年 初 工 作 | B1: 1.支付上年度所得税 | E1: 一般企业25%，高新企业15% 从现金取出放到利息中 | M1: =初始年财报!C21 -> 1 | O1: 综合费用
B2: 2.召开年度经营会议 | E2: 调整公司战略，制定当年经营和工作计划 | K2: 计划收入 | O2: =P5+O21+O22+O29+O33+O34+O40+O45+O48+O53 -> 0
B3: 3.市场竞标 | D3: 区域 | E3: 基础产品 | G3: 标准产品 | I3: 精密产品 | K3: 智能产品 | M3: 区域市场 订单总价 | O3: 订单 总额 | P3: 市场 投入
E4: 总价 | G4: 总价 | I4: 总价 | K4: 总价
D5: 本地 | M5: =SUM(E5:L5) -> 0 | O5: =SUM(M5:N8) -> 0
D6: 区域 | M6: =SUM(E6:L6) -> 0
D7: 全国 | M7: =SUM(E7:L7) -> 0
D8: 全球 | M8: =SUM(E8:L8) -> 0
B9: 1.短期贷款更新账期 年利率：10% | G9: 第一季度 | H9: 二季度 | I9: 第二季度 | J9: 四季度 | K9: 第三季度 | M9: 第四季度 | O9: 总计 | P9: 增减
E10: 到期还贷 | O10: =SUM(G10:N10) -> 0 | P10: =初始年财报!K7+O12-O10 -> 20
E11: 付利息 | O11: =SUM(G11:N11) -> 0
E12: 新增贷款 | O12: =SUM(G12:N12) -> 0
A13: 每季 度 工 作 | B13: 2.支付材料费用 支付前一季度订购的产品材料费，并将订单移至产品库 | G13: 第一季度 | H13: 二季度 | I13: 第二季度 | J13: 四季度 | K13: 第三季度 | M13: 第四季度 | O13: 总计
E14: 基础产品 | O14: =G14+I14+K14+M14 -> 0
E15: 标准产品 | O15: =G15+I15+K15+M15 -> 0
E16: 精密产品 | O16: =G16+I16+K16+M16 -> 0
E17: 智能产品 | O17: =G17+I17+K17+M17 -> 0
E18: 合计 | G18: =G14+G15+G16+G17 -> 0 | H18: =SUM(H14:H17) -> 0 | I18: =I14+I15+I16+I17 -> 0 | K18: =K14+K15+K16+K17 -> 0 | M18: =M14+M15+M16+M17 -> 0 | O18: =G18+I18+K18+M18 -> 0
A19: 每季 度 工 作 | B19: 3.产品进度更新 （每个在建交付产品向前移动一格，满格的移动到产品交付库）
B20: 4.生产线调整 变更产品 拆除变卖 新生产线投资安装 | G20: 第一季度 | H20: 二季度 | I20: 第二季度 | J20: 四季度 | K20: 第三季度 | M20: 第四季度 | O20: 总计
E21: 变更产品 | O21: =SUM(G21:N21) -> 0
E22: 生产线拆除 1M/条 | O22: =G22+I22+K22+M22 -> 0
E23: 生产线出售 从资产残值中取出相应金额到现金并记账 | O23: =SUM(G23:N25) -> 0
E26: 新生产线安装 | O26: =SUM(G26:N26) -> 0
E27: 建成生产线转固 | F27: 生产线残值 | O27: =SUM(G27:N27) -> 0
F28: 待折资产 | O28: =SUM(G28:N28) -> 0
B29: 5.人力资源管理 招聘/辞退/待岗/上岗/培训 | E29: 支付招聘、辞退、培训、待岗费用 | O29: =SUM(G29:N30) -> 0
B31: 6.生产线空位投放材料，发放工人工资 | E31: 支付交付产品的生产线使用人员工资 | O31: =SUM(G31:N32) -> 0
B33: 7.新技术研发投入 | E33: 技术研发 | O33: =SUM(G33:N33) -> 0
B34: 8.管理体系投入 | E34: 质量环境健康费用 | O34: =SUM(G34:N34) -> 0
B35: 9.下新供应链订单，以空桶代替，放到供应链订单上
B36: 10.更新应收账款，所有应收向左移动一格 | E36: 如应收账款进入现金区做记录 | O36: =SUM(G36:N37) -> 0
B38: 11.产品验收交付 | E38: 交货订单销售额 | O38: =SUM(G38:N38) -> 0
E39: 交货订单成本 | O39: =SUM(G39:N39) -> 0
B40: 12.支付管理人员费用 | E40: 每季1M | O40: =SUM(G40:N40) -> 0
O41: 总计 | P41: 增减
A42: 年末工作 | B42: 1.办理长期贷款 账期更新 | E42: 付利息 | G42: 年利率5% | P42: =初始年财报!K8+O44-O43 -> 0
E43: 到期还款 | G43: ------------------------------------------------------
E44: 办理新贷款 | G44: ------------------------------------------------------
B45: 2.支付生产线年度维护费1M/条 | G45: ------------------------------------------------------
...

Sheet 0年财报
B2: 损益表 | F2: 资产负债表
F3: 资产 | J3: 负 债 ＋ 权 益
B4: 销售收入 | C4: ='0年经营'!O38 -> 0 | F4: 非流动资产 | J4: 负债
B5: 直接成本 | C5: ='0年经营'!O39 -> 0 | F5: 在建生产线 | G5: ='0年经营'!O52 -> 0
F6: 厂房 | G6: =初始年财报!G6+'0年经营'!E60 -> 40
B7: 毛利 | C7: =C4-C5 -> 0 | F7: 生产线残值 | G7: =初始年财报!G7+'0年经营'!E61 -> 3 | J7: 短期负债 | K7: ='0年经营'!P10 -> 20
F8: 待折资产 | G8: =初始年财报!G8+'0年经营'!G61 -> 0 | J8: 长期负债 | K8: ='0年经营'!P42 -> 0
F9: 总非流动资产 | G9: =G5+G6+G7+G8 -> 43
B10: 综合费用 | C10: ='0年经营'!O2 -> 0 | J10: 总负债 | K10: =K6+K7+K8 -> 20
B11: 折旧 | C11: ='0年经营'!O51 -> 0 | F11: 流动资产
B13: 营业利润 | C13: =C7-C10-C11 -> 0 | F13: 现金 | G13: ='0年经营'!C59 -> 35 | J13: 总权益
F14: 应收款 | G14: =初始年财报!G14+'0年经营'!G60 -> 0
F15: 在制品 | H15: 手动输入 | J15: 股东资本 | K15: =初始年财报!K15 -> 50
B16: 财务收入/支出 | C16: ='0年经营'!C60 -> 0 | F16: 成品 | H16: 手动输入 | J16: 利润留存 | K16: =初始年财报!K16+初始年财报!K17 -> 19
B17: 额外收入/支出 | C17: ='0年经营'!C61 -> 0 | F17: 材料 | H17: 手动输入 | J17: 年度净利润 | K17: =C22 -> 0
F18: 所得税后现金 | G18: =G13-C21 -> 35
B19: 税前利润 | C19: =C13-C16+C17 -> 0 | F19: 总流动资产 | G19: =SUM(G14:G18) -> 35 | J19: 总股东权益 | K19: =K15+K16+K17 -> 69
B21: 所得税 | C21: =IF((FIXED(C19*C24,0)-0)<0,0,FIXED(C19*C24,0,TRUE)) -> 0
B22: 年度净利润 | C22: =C19-C21 -> 0 | F22: 总资产 | G22: =G9+G19 -> 78 | J22: 总负债权益 | K22: =K19+K10 -> 89
B24: 一般企业0.25 | D24: 手工输入
B25: 高新企业0.15
B26: 全额弥补亏损0

Sheet 1年经营
A1: 年 初 工 作 | B1: 1.支付上年度所得税 | E1: 一般企业25%，高新企业15% 从现金取出放到利息中 | M1: ='0年财报'!C21 -> 0 | O1: 综合费用
B2: 2.召开年度经营会议 | E2: 调整公司战略，制定当年经营和工作计划 | K2: 计划收入 | O2: =P5+O21+O22+O29+O33+O34+O40+O45+O48+O53 -> 0
B3: 3.市场竞标 | D3: 区域 | E3: 基础产品 | G3: 标准产品 | I3: 精密产品 | K3: 智能产品 | M3: 区域市场 订单总价 | O3: 订单 总额 | P3: 市场 投入
E4: 总价 | G4: 总价 | I4: 总价 | K4: 总价
D5: 本地 | M5: =SUM(E5:L5) -> 0 | O5: =SUM(M5:N8) -> 0
D6: 区域 | M6: =SUM(E6:L6) -> 0
D7: 全国 | M7: =SUM(E7:L7) -> 0
D8: 全球 | M8: =SUM(E8:L8) -> 0
A9: 每季工作 | B9: 1.短期贷款更新账期 年利率：10% | G9: 第一季度 | H9: 二季度 | I9: 第二季度 | J9: 四季度 | K9: 第三季度 | M9: 第四季度 | O9: 总计 | P9: 增减
E10: 到期还贷 | O10: =SUM(G10:N10) -> 0 | P10: ='0年财报'!K7+O12-O10 -> 20
E11: 付利息 | O11: =SUM(G11:N11) -> 0
E12: 新增贷款 | O12: =SUM(G12:N12) -> 0
A13: 每季 度 工 作 | B13: 2.支付材料费用 支付前一季度订购的产品材料费，并将订单移至产品库 | G13: 第一季度 | H13: 二季度 | I13: 第二季度 | J13: 四季度 | K13: 第三季度 | M13: 第四季度 | O13: 总计
E14: 基础产品 | O14: =G14+I14+K14+M14 -> 0
E15: 标准产品 | O15: =G15+I15+K15+M15 -> 0
E16: 精密产品 | O16: =G16+I16+K16+M16 -> 0
E17: 智能产品 | O17: =G17+I17+K17+M17 -> 0
E18: 合计 | G18: =G14+G15+G16+G17 -> 0 | H18: =SUM(H14:H17) -> 0 | I18: =I14+I15+I16+I17 -> 0 | K18: =K14+K15+K16+K17 -> 0 | M18: =M14+M15+M16+M17 -> 0 | O18: =G18+I18+K18+M18 -> 0
A19: 每季 度 工 作 | B19: 3.产品进度更新 （每个在建交付产品向前移动一格，满格的移动到产品交付库）
B20: 4.生产线调整 变更产品 拆除变卖 新生产线投资安装 | G20: 第一季度 | H20: 二季度 | I20: 第二季度 | J20: 四季度 | K20: 第三季度 | M20: 第四季度 | O20: 总计
E21: 变更产品 | O21: =SUM(G21:N21) -> 0
E22: 生产线拆除 1M/条 | O22: =G22+I22+K22+M22 -> 0
E23: 生产线出售 从资产残值中取出相应金额到现金并记账 | O23: =SUM(G23:N25) -> 0
E26: 新生产线安装 | O26: =SUM(G26:N26) -> 0
E27: 建成生产线转固 | F27: 生产线残值 | O27: =SUM(G27:N27) -> 0
F28: 待折资产 | O28: =SUM(G28:N28) -> 0
B29: 5.人力资源管理 招聘/辞退/待岗/上岗/培训 | E29: 支付招聘、辞退、培训、待岗费用 | O29: =SUM(G29:N30) -> 0
B31: 6.生产线空位投放材料，发放工人工资 | E31: 支付交付产品的生产线使用人员工资 | O31: =SUM(G31:N32) -> 0
B33: 7.新技术研发投入 | E33: 技术研发 | O33: =SUM(G33:N33) -> 0
B34: 8.管理体系投入 | E34: 质量环境健康费用 | O34: =SUM(G34:N34) -> 0
B35: 9.下新供应链订单，以空桶代替，放到供应链订单上
B36: 10.更新应收账款，所有应收向左移动一格 | E36: 如应收账款进入现金区做记录 | O36: =SUM(G36:N37) -> 0
B38: 11.产品验收交付 | E38: 交货订单销售额 | O38: =SUM(G38:N38) -> 0
E39: 交货订单成本 | O39: =SUM(G39:N39) -> 0
B40: 12.支付管理人员费用 | E40: 每季1M | O40: =SUM(G40:N40) -> 0
O41: 总计 | P41: 增减
A42: 年末工作 | B42: 1.办理长期贷款 账期更新 | E42: 付利息 | G42: 年利率5% | P42: ='0年财报'!K8+O44-O43 -> 0
E43: 到期还款 | G43: ------------------------------------------------------
E44: 办理新贷款 | G44: ------------------------------------------------------
B45: 2.支付生产线年度维护费 1M/条 | G45: ------------------------------------------------------
...

Sheet 1年财报
B2: 损益表 | F2: 资产负债表
F3: 资产 | J3: 负 债 ＋ 权 益
B4: 销售收入 | C4: ='1年经营'!O38 -> 0 | F4: 非流动资产 | J4: 负债
B5: 直接成本 | C5: ='1年经营'!O39 -> 0 | F5: 在建生产线 | G5: ='1年经营'!O52 -> 0
F6: 厂房 | G6: ='0年财报'!G6+'1年经营'!E60 -> 40
B7: 毛利 | C7: =C4-C5 -> 0 | F7: 生产线残值 | G7: ='0年财报'!G7+'1年经营'!E61 -> 3 | J7: 短期负债 | K7: ='1年经营'!P10 -> 20
F8: 待折资产 | G8: ='0年财报'!G8+'1年经营'!G61 -> 0 | J8: 长期负债 | K8: ='1年经营'!P42 -> 0
F9: 总非流动资产 | G9: =G5+G6+G7+G8 -> 43
B10: 综合费用 | C10: ='1年经营'!O2 -> 0 | J10: 总负债 | K10: =K6+K7+K8 -> 20
B11: 折旧 | C11: ='1年经营'!O51 -> 0 | F11: 流动资产
B13: 营业利润 | C13: =C7-C10-C11 -> 0 | F13: 现金 | G13: ='1年经营'!C59 -> 35 | J13: 总权益
F14: 应收款 | G14: ='0年财报'!G14+'1年经营'!O38-'1年经营'!O36 -> 0
F15: 在制品 | H15: 手动输入 | J15: 股东资本 | K15: ='0年财报'!K15 -> 50
B16: 财务收入/支出 | C16: ='1年经营'!C60 -> 0 | F16: 成品 | H16: 手动输入 | J16: 利润留存 | K16: ='0年财报'!K16+'0年财报'!K17 -> 19
B17: 额外收入/支出 | C17: ='1年经营'!C61 -> 0 | F17: 材料 | H17: 手动输入 | J17: 年度净利润 | K17: =C22 -> 0
F18: 所得税后现金 | G18: =G13-C21 -> 35
B19: 税前利润 | C19: =C13-C16+C17 -> 0 | F19: 总流动资产 | G19: =SUM(G14:G18) -> 35 | J19: 总股东权益 | K19: =K15+K16+K17 -> 69
B21: 所得税 | C21: =IF((FIXED(C19*C24,0)-0)<0,0,FIXED(C19*C24,0,TRUE)) -> 0
B22: 年度净利润 | C22: =C19-C21 -> 0 | F22: 总资产 | G22: =G9+G19 -> 78 | J22: 总负债权益 | K22: =K19+K10 -> 89
B24: 一般企业0.25 | D24: 手工输入
B25: 高新企业0.15
B26: 全额弥补亏损0

Sheet 2年经营
A1: 年 初 工 作 | B1: 1.支付上年度所得税 | E1: 一般企业25%，高新企业15% 从现金取出放到利息中 | M1: ='1年财报'!C21 -> 0 | O1: 综合费用
B2: 2.召开年度经营会议 | E2: 调整公司战略，制定当年经营和工作计划 | K2: 计划收入 | O2: =P5+O21+O22+O29+O33+O34+O40+O45+O48+O53 -> 0
B3: 3.市场竞标 | D3: 区域 | E3: 基础产品 | G3: 标准产品 | I3: 精密产品 | K3: 智能产品 | M3: 区域市场 订单总价 | O3: 订单 总额 | P3: 市场 投入
E4: 总价 | G4: 总价 | I4: 总价 | K4: 总价
D5: 本地 | M5: =SUM(E5:L5) -> 0 | O5: =SUM(M5:N8) -> 0
D6: 区域 | M6: =SUM(E6:L6) -> 0
D7: 全国 | M7: =SUM(E7:L7) -> 0
D8: 全球 | M8: =SUM(E8:L8) -> 0
A9: 每季工作 | B9: 1.短期贷款更新账期 年利率：10% | G9: 第一季度 | H9: 二季度 | I9: 第二季度 | J9: 四季度 | K9: 第三季度 | M9: 第四季度 | O9: 总计 | P9: 增减
E10: 到期还贷 | O10: =SUM(G10:N10) -> 0 | P10: ='1年财报'!K7+O12-O10 -> 20
E11: 付利息 | O11: =SUM(G11:N11) -> 0
E12: 新增贷款 | O12: =SUM(G12:N12) -> 0
A13: 每季 度 工 作 | B13: 2.支付材料费用 支付前一季度订购的产品材料费，并将订单移至产品库 | G13: 第一季度 | H13: 二季度 | I13: 第二季度 | J13: 四季度 | K13: 第三季度 | M13: 第四季度 | O13: 总计
E14: 基础产品 | O14: =G14+I14+K14+M14 -> 0
E15: 标准产品 | O15: =G15+I15+K15+M15 -> 0
E16: 精密产品 | O16: =G16+I16+K16+M16 -> 0
E17: 智能产品 | O17: =G17+I17+K17+M17 -> 0
E18: 合计 | G18: =G14+G15+G16+G17 -> 0 | H18: =SUM(H14:H17) -> 0 | I18: =I14+I15+I16+I17 -> 0 | K18: =K14+K15+K16+K17 -> 0 | M18: =M14+M15+M16+M17 -> 0 | O18: =G18+I18+K18+M18 -> 0
A19: 每季 度 工 作 | B19: 3.产品进度更新 （每个在建交付产品向前移动一格，满格的移动到产品交付库）
B20: 4.生产线调整 变更产品 拆除变卖 新生产线投资安装 | G20: 第一季度 | H20: 二季度 | I20: 第二季度 | J20: 四季度 | K20: 第三季度 | M20: 第四季度 | O20: 总计
E21: 变更产品 | O21: =SUM(G21:N21) -> 0
E22: 生产线拆除 1M/条 | O22: =G22+I22+K22+M22 -> 0
E23: 生产线出售 从资产残值中取出相应金额到现金并记账 | O23: =SUM(G23:N25) -> 0
E26: 新生产线安装 | O26: =SUM(G26:N26) -> 0
E27: 建成生产线转固 | F27: 生产线残值 | O27: =SUM(G27:N27) -> 0
F28: 待折资产 | O28: =SUM(G28:N28) -> 0
B29: 5.人力资源管理 招聘/辞退/待岗/上岗/培训 | E29: 支付招聘、辞退、培训、待岗费用 | O29: =SUM(G29:N30) -> 0
B31: 6.生产线空位投放材料，发放工人工资 | E31: 支付交付产品的生产线使用人员工资 | O31: =SUM(G31:N32) -> 0
B33: 7.新技术研发投入 | E33: 技术研发 | O33: =SUM(G33:N33) -> 0
B34: 8.管理体系投入 | E34: 质量环境健康费用 | O34: =SUM(G34:N34) -> 0
B35: 9.下新供应链订单，以空桶代替，放到供应链订单上
B36: 10.更新应收账款，所有应收向左移动一格 | E36: 如应收账款进入现金区做记录 | O36: =SUM(G36:N37) -> 0
B38: 11.产品验收交付 | E38: 交货订单销售额 | O38: =SUM(G38:N38) -> 0
E39: 交货订单成本 | O39: =SUM(G39:N39) -> 0
B40: 12.支付管理人员费用 | E40: 每季1M | O40: =SUM(G40:N40) -> 0
O41: 总计 | P41: 增减
A42: 年末工作 | B42: 1.办理长期贷款 账期更新 | E42: 付利息 | G42: 年利率5% | P42: ='1年财报'!K8+O44-O43 -> 0
E43: 到期还款 | G43: ------------------------------------------------------
E44: 办理新贷款 | G44: ------------------------------------------------------
B45: 2.支付生产线年度维护费 1M/条 | G45: ------------------------------------------------------
...

Sheet 2年财报
B2: 损益表 | F2: 资产负债表
F3: 资产 | J3: 负 债 ＋ 权 益
B4: 销售收入 | C4: ='2年经营'!O38 -> 0 | F4: 非流动资产 | J4: 负债
B5: 直接成本 | C5: ='2年经营'!O39 -> 0 | F5: 在建生产线 | G5: ='2年经营'!O52 -> 0
F6: 厂房 | G6: ='1年财报'!G6+'2年经营'!E60 -> 40
B7: 毛利 | C7: =C4-C5 -> 0 | F7: 生产线残值 | G7: ='1年财报'!G7+'2年经营'!E61 -> 3 | J7: 短期负债 | K7: ='2年经营'!P10 -> 20
F8: 待折资产 | G8: ='1年财报'!G8+'2年经营'!G61 -> 0 | J8: 长期负债 | K8: ='2年经营'!P42 -> 0
F9: 总非流动资产 | G9: =G5+G6+G7+G8 -> 43
B10: 综合费用 | C10: ='2年经营'!O2 -> 0 | J10: 总负债 | K10: =K6+K7+K8 -> 20
B11: 折旧 | C11: ='2年经营'!O51 -> 0 | F11: 流动资产
B13: 营业利润 | C13: =C7-C10-C11 -> 0 | F13: 现金 | G13: ='2年经营'!C59 -> 35 | J13: 总权益
F14: 应收款 | G14: ='1年财报'!G14+'2年经营'!O38-'2年经营'!O36 -> 0
F15: 在制品 | H15: 手动输入 | J15: 股东资本 | K15: ='1年财报'!K15 -> 50
B16: 财务收入/支出 | C16: ='2年经营'!C60 -> 0 | F16: 成品 | H16: 手动输入 | J16: 利润留存 | K16: ='1年财报'!K16+'1年财报'!K17 -> 19
B17: 额外收入/支出 | C17: ='2年经营'!C61 -> 0 | F17: 材料 | H17: 手动输入 | J17: 年度净利润 | K17: =C22 -> 0
F18: 所得税后现金 | G18: =G13-C21 -> 35
B19: 税前利润 | C19: =C13-C16+C17 -> 0 | F19: 总流动资产 | G19: =SUM(G14:G18) -> 35 | J19: 总股东权益 | K19: =K15+K16+K17 -> 69
B21: 所得税 | C21: =IF((FIXED(C19*C24,0)-0)<0,0,FIXED(C19*C24,0,TRUE)) -> 0
B22: 年度净利润 | C22: =C19-C21 -> 0 | F22: 总资产 | G22: =G9+G19 -> 78 | J22: 总负债权益 | K22: =K19+K10 -> 89
B24: 一般企业0.25 | D24: 手工输入
B25: 高新企业0.15
B26: 全额弥补亏损0

Sheet 3年经营
A1: 年 初 工 作 | B1: 1.支付上年度所得税 | E1: 一般企业25%，高新企业15% 从现金取出放到利息中 | M1: ='2年财报'!C21 -> 0 | O1: 综合费用
B2: 2.召开年度经营会议 | E2: 调整公司战略，制定当年经营和工作计划 | K2: 计划收入 | O2: =P5+O21+O22+O29+O33+O34+O40+O45+O48+O53 -> 0
B3: 3.市场竞标 | D3: 区域 | E3: 基础产品 | G3: 标准产品 | I3: 精密产品 | K3: 智能产品 | M3: 区域市场 订单总价 | O3: 订单 总额 | P3: 市场 投入
E4: 总价 | G4: 总价 | I4: 总价 | K4: 总价
D5: 本地 | M5: =SUM(E5:L5) -> 0 | O5: =SUM(M5:N8) -> 0
D6: 区域 | M6: =SUM(E6:L6) -> 0
D7: 全国 | M7: =SUM(E7:L7) -> 0
D8: 全球 | M8: =SUM(E8:L8) -> 0
A9: 每季工作 | B9: 1.短期贷款更新账期 年利率：10% | G9: 第一季度 | H9: 二季度 | I9: 第二季度 | J9: 四季度 | K9: 第三季度 | M9: 第四季度 | O9: 总计 | P9: 增减
E10: 到期还贷 | O10: =SUM(G10:N10) -> 0 | P10: ='2年财报'!K7+O12-O10 -> 20
E11: 付利息 | O11: =SUM(G11:N11) -> 0
E12: 新增贷款 | O12: =SUM(G12:N12) -> 0
A13: 每季 度 工 作 | B13: 2.支付材料费用 支付前一季度订购的产品材料费，并将订单移至产品库 | G13: 第一季度 | H13: 二季度 | I13: 第二季度 | J13: 四季度 | K13: 第三季度 | M13: 第四季度 | O13: 总计
E14: 基础产品 | O14: =G14+I14+K14+M14 -> 0
E15: 标准产品 | O15: =G15+I15+K15+M15 -> 0
E16: 精密产品 | O16: =G16+I16+K16+M16 -> 0
E17: 智能产品 | O17: =G17+I17+K17+M17 -> 0
E18: 合计 | G18: =G14+G15+G16+G17 -> 0 | H18: =SUM(H14:H17) -> 0 | I18: =I14+I15+I16+I17 -> 0 | K18: =K14+K15+K16+K17 -> 0 | M18: =M14+M15+M16+M17 -> 0 | O18: =G18+I18+K18+M18 -> 0
A19: 每季 度 工 作 | B19: 3.产品进度更新 （每个在建交付产品向前移动一格，满格的移动到产品交付库）
B20: 4.生产线调整 变更产品 拆除变卖 新生产线投资安装 | G20: 第一季度 | H20: 二季度 | I20: 第二季度 | J20: 四季度 | K20: 第三季度 | M20: 第四季度 | O20: 总计
E21: 变更产品 | O21: =SUM(G21:N21) -> 0
E22: 生产线拆除 1M/条 | O22: =G22+I22+K22+M22 -> 0
E23: 生产线出售 从资产残值中取出相应金额到现金并记账 | O23: =SUM(G23:N25) -> 0
E26: 新生产线安装 | O26: =SUM(G26:N26) -> 0
E27: 建成生产线转固 | F27: 生产线残值 | O27: =SUM(G27:N27) -> 0
F28: 待折资产 | O28: =SUM(G28:N28) -> 0
B29: 5.人力资源管理 招聘/辞退/待岗/上岗/培训 | E29: 支付招聘、辞退、培训、待岗费用 | O29: =SUM(G29:N30) -> 0
B31: 6.生产线空位投放材料，发放工人工资 | E31: 支付交付产品的生产线使用人员工资 | O31: =SUM(G31:N32) -> 0
B33: 7.新技术研发投入 | E33: 技术研发 | O33: =SUM(G33:N33) -> 0
B34: 8.管理体系投入 | E34: 质量环境健康费用 | O34: =SUM(G34:N34) -> 0
B35: 9.下新供应链订单，以空桶代替，放到供应链订单上
B36: 10.更新应收账款，所有应收向左移动一格 | E36: 如应收账款进入现金区做记录 | O36: =SUM(G36:N37) -> 0
B38: 11.产品验收交付 | E38: 交货订单销售额 | O38: =SUM(G38:N38) -> 0
E39: 交货订单成本 | O39: =SUM(G39:N39) -> 0
B40: 12.支付管理人员费用 | E40: 每季1M | O40: =SUM(G40:N40) -> 0
O41: 总计 | P41: 增减
A42: 年末工作 | B42: 1.办理长期贷款 账期更新 | E42: 付利息 | G42: 年利率5% | P42: ='2年财报'!K8+O44-O43 -> 0
E43: 到期还款 | G43: ------------------------------------------------------
E44: 办理新贷款 | G44: ------------------------------------------------------
B45: 2.支付生产线年度维护费 1M/条 | G45: ------------------------------------------------------
...

Sheet 3年财报
B2: 损益表 | F2: 资产负债表
F3: 资产 | J3: 负 债 ＋ 权 益
B4: 销售收入 | C4: ='3年经营'!O38 -> 0 | F4: 非流动资产 | J4: 负债
B5: 直接成本 | C5: ='3年经营'!O39 -> 0 | F5: 在建生产线 | G5: ='3年经营'!O52 -> 0
F6: 厂房 | G6: ='2年财报'!G6+'3年经营'!E60 -> 40
B7: 毛利 | C7: =C4-C5 -> 0 | F7: 生产线残值 | G7: ='2年财报'!G7+'3年经营'!E61 -> 3 | J7: 短期负债 | K7: ='3年经营'!P10 -> 20
F8: 待折资产 | G8: ='2年财报'!G8+'3年经营'!G61 -> 0 | J8: 长期负债 | K8: ='3年经营'!P42 -> 0
F9: 总非流动资产 | G9: =G5+G6+G7+G8 -> 43
B10: 综合费用 | C10: ='3年经营'!O2 -> 0 | J10: 总负债 | K10: =K6+K7+K8 -> 20
B11: 折旧 | C11: ='3年经营'!O51 -> 0 | F11: 流动资产
B13: 营业利润 | C13: =C7-C10-C11 -> 0 | F13: 现金 | G13: ='3年经营'!C59 -> 35 | J13: 总权益
F14: 应收款 | G14: ='2年财报'!G14+'3年经营'!O38-'3年经营'!O36 -> 0
F15: 在制品 | H15: 手动输入 | J15: 股东资本 | K15: ='2年财报'!K15 -> 50
B16: 财务收入/支出 | C16: ='3年经营'!C60 -> 0 | F16: 成品 | H16: 手动输入 | J16: 利润留存 | K16: ='2年财报'!K16+'2年财报'!K17 -> 19
B17: 额外收入/支出 | C17: ='3年经营'!C61 -> 0 | F17: 材料 | H17: 手动输入 | J17: 年度净利润 | K17: =C22 -> 0
F18: 所得税后现金 | G18: =G13-C21 -> 35
B19: 税前利润 | C19: =C13-C16+C17 -> 0 | F19: 总流动资产 | G19: =SUM(G14:G18) -> 35 | J19: 总股东权益 | K19: =K15+K16+K17 -> 69
B21: 所得税 | C21: =IF((FIXED(C19*C24,0)-0)<0,0,FIXED(C19*C24,0,TRUE)) -> 0
B22: 年度净利润 | C22: =C19-C21 -> 0 | F22: 总资产 | G22: =G9+G19 -> 78 | J22: 总负债权益 | K22: =K19+K10 -> 89
B24: 一般企业0.25 | D24: 手工输入
B25: 高新企业0.15
B26: 全额弥补亏损0

Sheet 4年经营
A1: 年 初 工 作 | B1: 1.支付上年度所得税 | E1: 一般企业25%，高新企业15% 从现金取出放到利息中 | M1: ='3年财报'!C21 -> 0 | O1: 综合费用
B2: 2.召开年度经营会议 | E2: 调整公司战略，制定当年经营和工作计划 | K2: 计划收入 | O2: =P5+O21+O22+O29+O33+O34+O40+O45+O48+O53 -> 0
B3: 3.市场竞标 | D3: 区域 | E3: 基础产品 | G3: 标准产品 | I3: 精密产品 | K3: 智能产品 | M3: 区域市场 订单总价 | O3: 订单 总额 | P3: 市场 投入
E4: 总价 | G4: 总价 | I4: 总价 | K4: 总价
D5: 本地 | M5: =SUM(E5:L5) -> 0 | O5: =SUM(M5:N8) -> 0
D6: 区域 | M6: =SUM(E6:L6) -> 0
D7: 全国 | M7: =SUM(E7:L7) -> 0
D8: 全球 | M8: =SUM(E8:L8) -> 0
A9: 每季工作 | B9: 1.短期贷款更新账期 年利率：10% | G9: 第一季度 | H9: 二季度 | I9: 第二季度 | J9: 四季度 | K9: 第三季度 | M9: 第四季度 | O9: 总计 | P9: 增减
E10: 到期还贷 | O10: =SUM(G10:N10) -> 0 | P10: ='3年财报'!K7+O12-O10 -> 20
E11: 付利息 | O11: =SUM(G11:N11) -> 0
E12: 新增贷款 | O12: =SUM(G12:N12) -> 0
A13: 每季 度 工 作 | B13: 2.支付材料费用 支付前一季度订购的产品材料费，并将订单移至产品库 | G13: 第一季度 | H13: 二季度 | I13: 第二季度 | J13: 四季度 | K13: 第三季度 | M13: 第四季度 | O13: 总计
E14: 基础产品 | O14: =G14+I14+K14+M14 -> 0
E15: 标准产品 | O15: =G15+I15+K15+M15 -> 0
E16: 精密产品 | O16: =G16+I16+K16+M16 -> 0
E17: 智能产品 | O17: =G17+I17+K17+M17 -> 0
E18: 合计 | G18: =G14+G15+G16+G17 -> 0 | H18: =SUM(H14:H17) -> 0 | I18: =I14+I15+I16+I17 -> 0 | K18: =K14+K15+K16+K17 -> 0 | M18: =M14+M15+M16+M17 -> 0 | O18: =G18+I18+K18+M18 -> 0
A19: 每季 度 工 作 | B19: 3.产品进度更新 （每个在建交付产品向前移动一格，满格的移动到产品交付库）
B20: 4.生产线调整 变更产品 拆除变卖 新生产线投资安装 | G20: 第一季度 | H20: 二季度 | I20: 第二季度 | J20: 四季度 | K20: 第三季度 | M20: 第四季度 | O20: 总计
E21: 变更产品 | O21: =SUM(G21:N21) -> 0
E22: 生产线拆除 1M/条 | O22: =G22+I22+K22+M22 -> 0
E23: 生产线出售 从资产残值中取出相应金额到现金并记账 | O23: =SUM(G23:N25) -> 0
E26: 新生产线安装 | O26: =SUM(G26:N26) -> 0
E27: 建成生产线转固 | F27: 生产线残值 | O27: =SUM(G27:N27) -> 0
F28: 待折资产 | O28: =SUM(G28:N28) -> 0
B29: 5.人力资源管理 招聘/辞退/待岗/上岗/培训 | E29: 支付招聘、辞退、培训、待岗费用 | O29: =SUM(G29:N30) -> 0
B31: 6.生产线空位投放材料，发放工人工资 | E31: 支付交付产品的生产线使用人员工资 | O31: =SUM(G31:N32) -> 0
B33: 7.新技术研发投入 | E33: 技术研发 | O33: =SUM(G33:N33) -> 0
B34: 8.管理体系投入 | E34: 质量环境健康费用 | O34: =SUM(G34:N34) -> 0
B35: 9.下新供应链订单，以空桶代替，放到供应链订单上
B36: 10.更新应收账款，所有应收向左移动一格 | E36: 如应收账款进入现金区做记录 | O36: =SUM(G36:N37) -> 0
B38: 11.产品验收交付 | E38: 交货订单销售额 | O38: =SUM(G38:N38) -> 0
E39: 交货订单成本 | O39: =SUM(G39:N39) -> 0
B40: 12.支付管理人员费用 | E40: 每季1M | O40: =SUM(G40:N40) -> 0
O41: 总计 | P41: 增减
A42: 年末工作 | B42: 1.办理长期贷款 账期更新 | E42: 付利息 | G42: 年利率5% | P42: ='3年财报'!K8+O44-O43 -> 0
E43: 到期还款 | G43: ------------------------------------------------------
E44: 办理新贷款 | G44: ------------------------------------------------------
B45: 2.支付生产线年度维护费 1M/条 | G45: ------------------------------------------------------
...

Sheet 4年财报
B2: 损益表 | F2: 资产负债表
F3: 资产 | J3: 负 债 ＋ 权 益
B4: 销售收入 | C4: ='4年经营'!O38 -> 0 | F4: 非流动资产 | J4: 负债
B5: 直接成本 | C5: ='4年经营'!O39 -> 0 | F5: 在建生产线 | G5: ='4年经营'!O52 -> 0
F6: 厂房 | G6: ='3年财报'!G6+'4年经营'!E60 -> 40
B7: 毛利 | C7: =C4-C5 -> 0 | F7: 生产线残值 | G7: ='3年财报'!G7+'4年经营'!E61 -> 3 | J7: 短期负债 | K7: ='4年经营'!P10 -> 20
F8: 待折资产 | G8: ='3年财报'!G8+'4年经营'!G61 -> 0 | J8: 长期负债 | K8: ='4年经营'!P42 -> 0
F9: 总非流动资产 | G9: =G5+G6+G7+G8 -> 43
B10: 综合费用 | C10: ='4年经营'!O2 -> 0 | J10: 总负债 | K10: =K6+K7+K8 -> 20
B11: 折旧 | C11: ='4年经营'!O51 -> 0 | F11: 流动资产
B13: 营业利润 | C13: =C7-C10-C11 -> 0 | F13: 现金 | G13: ='4年经营'!C59 -> 35 | J13: 总权益
F14: 应收款 | G14: ='3年财报'!G14+'4年经营'!O38-'4年经营'!O36 -> 0
F15: 在制品 | H15: 手动输入 | J15: 股东资本 | K15: ='3年财报'!K15 -> 50
B16: 财务收入/支出 | C16: ='4年经营'!C60 -> 0 | F16: 成品 | H16: 手动输入 | J16: 利润留存 | K16: ='3年财报'!K16+'3年财报'!K17 -> 19
B17: 额外收入/支出 | C17: ='4年经营'!C61 -> 0 | F17: 材料 | H17: 手动输入 | J17: 年度净利润 | K17: =C22 -> 0
F18: 所得税后现金 | G18: =G13-C21 -> 35
B19: 税前利润 | C19: =C13-C16+C17 -> 0 | F19: 总流动资产 | G19: =SUM(G14:G18) -> 35 | J19: 总股东权益 | K19: =K15+K16+K17 -> 69
B21: 所得税 | C21: =IF((FIXED(C19*C24,0)-0)<0,0,FIXED(C19*C24,0,TRUE)) -> 0
B22: 年度净利润 | C22: =C19-C21 -> 0 | F22: 总资产 | G22: =G9+G19 -> 78 | J22: 总负债权益 | K22: =K19+K10 -> 89
B24: 一般企业0.25 | D24: 手工输入
B25: 高新企业0.15
B26: 全额弥补亏损0

Sheet 5年经营
A1: 年 初 工 作 | B1: 1.支付上年度所得税 | E1: 一般企业25%，高新企业15% 从现金取出放到利息中 | M1: ='4年财报'!C21 -> 0 | O1: 综合费用
B2: 2.召开年度经营会议 | E2: 调整公司战略，制定当年经营和工作计划 | K2: 计划收入 | O2: =P5+O21+O22+O29+O33+O34+O40+O45+O48+O53 -> 0
B3: 3.市场竞标 | D3: 区域 | E3: 基础产品 | G3: 标准产品 | I3: 精密产品 | K3: 智能产品 | M3: 区域市场 订单总价 | O3: 订单 总额 | P3: 市场 投入
E4: 总价 | G4: 总价 | I4: 总价 | K4: 总价
D5: 本地 | M5: =SUM(E5:L5) -> 0 | O5: =SUM(M5:N8) -> 0
D6: 区域 | M6: =SUM(E6:L6) -> 0
D7: 全国 | M7: =SUM(E7:L7) -> 0
D8: 全球 | M8: =SUM(E8:L8) -> 0
A9: 每季工作 | B9: 1.短期贷款更新账期 年利率：10% | G9: 第一季度 | H9: 二季度 | I9: 第二季度 | J9: 四季度 | K9: 第三季度 | M9: 第四季度 | O9: 总计 | P9: 增减
E10: 到期还贷 | O10: =SUM(G10:N10) -> 0 | P10: ='4年财报'!K7+O12-O10 -> 20
E11: 付利息 | O11: =SUM(G11:N11) -> 0
E12: 新增贷款 | O12: =SUM(G12:N12) -> 0
A13: 每季 度 工 作 | B13: 2.支付材料费用 支付前一季度订购的产品材料费，并将订单移至产品库 | G13: 第一季度 | H13: 二季度 | I13: 第二季度 | J13: 四季度 | K13: 第三季度 | M13: 第四季度 | O13: 总计
E14: 基础产品 | O14: =G14+I14+K14+M14 -> 0
E15: 标准产品 | O15: =G15+I15+K15+M15 -> 0
E16: 精密产品 | O16: =G16+I16+K16+M16 -> 0
E17: 智能产品 | O17: =G17+I17+K17+M17 -> 0
E18: 合计 | G18: =G14+G15+G16+G17 -> 0 | H18: =SUM(H14:H17) -> 0 | I18: =I14+I15+I16+I17 -> 0 | K18: =K14+K15+K16+K17 -> 0 | M18: =M14+M15+M16+M17 -> 0 | O18: =G18+I18+K18+M18 -> 0
A19: 每季 度 工 作 | B19: 3.产品进度更新 （每个在建交付产品向前移动一格，满格的移动到产品交付库）
B20: 4.生产线调整 变更产品 拆除变卖 新生产线投资安装 | G20: 第一季度 | H20: 二季度 | I20: 第二季度 | J20: 四季度 | K20: 第三季度 | M20: 第四季度 | O20: 总计
E21: 变更产品 | O21: =SUM(G21:N21) -> 0
E22: 生产线拆除 1M/条 | O22: =G22+I22+K22+M22 -> 0
E23: 生产线出售 从资产残值中取出相应金额到现金并记账 | O23: =SUM(G23:N25) -> 0
E26: 新生产线安装 | O26: =SUM(G26:N26) -> 0
E27: 建成生产线转固 | F27: 生产线残值 | O27: =SUM(G27:N27) -> 0
F28: 待折资产 | O28: =SUM(G28:N28) -> 0
B29: 5.人力资源管理 招聘/辞退/待岗/上岗/培训 | E29: 支付招聘、辞退、培训、待岗费用 | O29: =SUM(G29:N30) -> 0
B31: 6.生产线空位投放材料，发放工人工资 | E31: 支付交付产品的生产线使用人员工资 | O31: =SUM(G31:N32) -> 0
B33: 7.新技术研发投入 | E33: 技术研发 | O33: =SUM(G33:N33) -> 0
B34: 8.管理体系投入 | E34: 质量环境健康费用 | O34: =SUM(G34:N34) -> 0
B35: 9.下新供应链订单，以空桶代替，放到供应链订单上
B36: 10.更新应收账款，所有应收向左移动一格 | E36: 如应收账款进入现金区做记录 | O36: =SUM(G36:N37) -> 0
B38: 11.产品验收交付 | E38: 交货订单销售额 | O38: =SUM(G38:N38) -> 0
E39: 交货订单成本 | O39: =SUM(G39:N39) -> 0
B40: 12.支付管理人员费用 | E40: 每季1M | O40: =SUM(G40:N40) -> 0
O41: 总计 | P41: 增减
A42: 年末工作 | B42: 1.办理长期贷款 账期更新 | E42: 付利息 | G42: 年利率5% | P42: ='4年财报'!K8+O44-O43 -> 0
E43: 到期还款 | G43: ------------------------------------------------------
E44: 办理新贷款 | G44: ------------------------------------------------------
B45: 2.支付生产线年度维护费 1M/条 | G45: ------------------------------------------------------
...

Sheet 5年财报
B2: 损益表 | F2: 资产负债表
F3: 资产 | J3: 负 债 ＋ 权 益
B4: 销售收入 | C4: ='5年经营'!O38 -> 0 | F4: 非流动资产 | J4: 负债
B5: 直接成本 | C5: ='5年经营'!O39 -> 0 | F5: 在建生产线 | G5: ='5年经营'!O52 -> 0
F6: 厂房 | G6: ='4年财报'!G6+'5年经营'!E60 -> 40
B7: 毛利 | C7: =C4-C5 -> 0 | F7: 生产线残值 | G7: ='4年财报'!G7+'5年经营'!E61 -> 3 | J7: 短期负债 | K7: ='5年经营'!P10 -> 20
F8: 待折资产 | G8: ='4年财报'!G8+'5年经营'!G61 -> 0 | J8: 长期负债 | K8: ='5年经营'!P42 -> 0
F9: 总非流动资产 | G9: =G5+G6+G7+G8 -> 43
B10: 综合费用 | C10: ='5年经营'!O2 -> 0 | J10: 总负债 | K10: =K6+K7+K8 -> 20
B11: 折旧 | C11: ='5年经营'!O51 -> 0 | F11: 流动资产
B13: 营业利润 | C13: =C7-C10-C11 -> 0 | F13: 现金 | G13: ='5年经营'!C59 -> 35 | J13: 总权益
F14: 应收款 | G14: ='4年财报'!G14+'5年经营'!O38-'5年经营'!O36 -> 0
F15: 在制品 | H15: 手动输入 | J15: 股东资本 | K15: ='4年财报'!K15 -> 50
B16: 财务收入/支出 | C16: ='5年经营'!C60 -> 0 | F16: 成品 | H16: 手动输入 | J16: 利润留存 | K16: ='4年财报'!K16+'4年财报'!K17 -> 19
B17: 额外收入/支出 | C17: ='5年经营'!C61 -> 0 | F17: 材料 | H17: 手动输入 | J17: 年度净利润 | K17: =C22 -> 0
F18: 所得税后现金 | G18: =G13-C21 -> 35
B19: 税前利润 | C19: =C13-C16+C17 -> 0 | F19: 总流动资产 | G19: =SUM(G14:G18) -> 35 | J19: 总股东权益 | K19: =K15+K16+K17 -> 69
B21: 所得税 | C21: =IF((FIXED(C19*C24,0)-0)<0,0,FIXED(C19*C24,0,TRUE)) -> 0
B22: 年度净利润 | C22: =C19-C21 -> 0 | F22: 总资产 | G22: =G9+G19 -> 78 | J22: 总负债权益 | K22: =K19+K10 -> 89
B24: 一般企业0.25 | D24: 手工输入
B25: 高新企业0.15
B26: 全额弥补亏损0

Sheet 6年经营
A1: 年 初 工 作 | B1: 1.支付上年度所得税 | E1: 一般企业25%，高新企业15% 从现金取出放到利息中 | M1: ='5年财报'!C21 -> 0 | O1: 综合费用
B2: 2.召开年度经营会议 | E2: 调整公司战略，制定当年经营和工作计划 | K2: 计划收入 | O2: =P5+O21+O22+O29+O33+O34+O40+O45+O48+O53 -> 0
B3: 3.市场竞标 | D3: 区域 | E3: 基础产品 | G3: 标准产品 | I3: 精密产品 | K3: 智能产品 | M3: 区域市场 订单总价 | O3: 订单 总额 | P3: 市场 投入
E4: 总价 | G4: 总价 | I4: 总价 | K4: 总价
D5: 本地 | M5: =SUM(E5:L5) -> 0 | O5: =SUM(M5:N8) -> 0
D6: 区域 | M6: =SUM(E6:L6) -> 0
D7: 全国 | M7: =SUM(E7:L7) -> 0
D8: 全球 | M8: =SUM(E8:L8) -> 0
A9: 每季工作 | B9: 1.短期贷款更新账期 年利率：10% | G9: 第一季度 | H9: 二季度 | I9: 第二季度 | J9: 四季度 | K9: 第三季度 | M9: 第四季度 | O9: 总计 | P9: 增减
E10: 到期还贷 | O10: =SUM(G10:N10) -> 0 | P10: ='5年财报'!K7+O12-O10 -> 20
E11: 付利息 | O11: =SUM(G11:N11) -> 0
E12: 新增贷款 | O12: =SUM(G12:N12) -> 0
A13: 每季 度 工 作 | B13: 2.支付材料费用 支付前一季度订购的产品材料费，并将订单移至产品库 | G13: 第一季度 | H13: 二季度 | I13: 第二季度 | J13: 四季度 | K13: 第三季度 | M13: 第四季度 | O13: 总计
E14: 基础产品 | O14: =G14+I14+K14+M14 -> 0
E15: 标准产品 | O15: =G15+I15+K15+M15 -> 0
E16: 精密产品 | O16: =G16+I16+K16+M16 -> 0
E17: 智能产品 | O17: =G17+I17+K17+M17 -> 0
E18: 合计 | G18: =G14+G15+G16+G17 -> 0 | H18: =SUM(H14:H17) -> 0 | I18: =I14+I15+I16+I17 -> 0 | K18: =K14+K15+K16+K17 -> 0 | M18: =M14+M15+M16+M17 -> 0 | O18: =G18+I18+K18+M18 -> 0
A19: 每季 度 工 作 | B19: 3.产品进度更新 （每个在建交付产品向前移动一格，满格的移动到产品交付库）
B20: 4.生产线调整 变更产品 拆除变卖 新生产线投资安装 | G20: 第一季度 | H20: 二季度 | I20: 第二季度 | J20: 四季度 | K20: 第三季度 | M20: 第四季度 | O20: 总计
E21: 变更产品 | O21: =SUM(G21:N21) -> 0
E22: 生产线拆除 1M/条 | O22: =G22+I22+K22+M22 -> 0
E23: 生产线出售 从资产残值中取出相应金额到现金并记账 | O23: =SUM(G23:N25) -> 0
E26: 新生产线安装 | O26: =SUM(G26:N26) -> 0
E27: 建成生产线转固 | F27: 生产线残值 | O27: =SUM(G27:N27) -> 0
F28: 待折资产 | O28: =SUM(G28:N28) -> 0
B29: 5.人力资源管理 招聘/辞退/待岗/上岗/培训 | E29: 支付招聘、辞退、培训、待岗费用 | O29: =SUM(G29:N30) -> 0
B31: 6.生产线空位投放材料，发放工人工资 | E31: 支付交付产品的生产线使用人员工资 | O31: =SUM(G31:N32) -> 0
B33: 7.新技术研发投入 | E33: 技术研发 | O33: =SUM(G33:N33) -> 0
B34: 8.管理体系投入 | E34: 质量环境健康费用 | O34: =SUM(G34:N34) -> 0
B35: 9.下新供应链订单，以空桶代替，放到供应链订单上
B36: 10.更新应收账款，所有应收向左移动一格 | E36: 如应收账款进入现金区做记录 | O36: =SUM(G36:N37) -> 0
B38: 11.产品验收交付 | E38: 交货订单销售额 | O38: =SUM(G38:N38) -> 0
E39: 交货订单成本 | O39: =SUM(G39:N39) -> 0
B40: 12.支付管理人员费用 | E40: 每季1M | O40: =SUM(G40:N40) -> 0
O41: 总计 | P41: 增减
A42: 年末工作 | B42: 1.办理长期贷款 账期更新 | E42: 付利息 | G42: 年利率5% | P42: ='5年财报'!K8+O44-O43 -> 0
E43: 到期还款 | G43: ------------------------------------------------------
E44: 办理新贷款 | G44: ------------------------------------------------------
B45: 2.支付生产线年度维护费 1M/条 | G45: ------------------------------------------------------
...

Sheet 6年财报
B2: 损益表 | F2: 资产负债表
F3: 资产 | J3: 负 债 ＋ 权 益
B4: 销售收入 | C4: ='6年经营'!O38 -> 0 | F4: 非流动资产 | J4: 负债
B5: 直接成本 | C5: ='6年经营'!O39 -> 0 | F5: 在建生产线 | G5: ='6年经营'!O52 -> 0
F6: 厂房 | G6: ='5年财报'!G6+'6年经营'!E60 -> 40
B7: 毛利 | C7: =C4-C5 -> 0 | F7: 生产线残值 | G7: ='5年财报'!G7+'6年经营'!E61 -> 3 | J7: 短期负债 | K7: ='6年经营'!P10 -> 20
F8: 待折资产 | G8: ='5年财报'!G8+'6年经营'!G61 -> 0 | J8: 长期负债 | K8: ='6年经营'!P42 -> 0
F9: 总非流动资产 | G9: =G5+G6+G7+G8 -> 43
B10: 综合费用 | C10: ='6年经营'!O2 -> 0 | J10: 总负债 | K10: =K6+K7+K8 -> 20
B11: 折旧 | C11: ='6年经营'!O51 -> 0 | F11: 流动资产
B13: 营业利润 | C13: =C7-C10-C11 -> 0 | F13: 现金 | G13: ='6年经营'!C59 -> 35 | J13: 总权益
F14: 应收款 | G14: ='5年财报'!G14+'6年经营'!O38-'6年经营'!O36 -> 0
F15: 在制品 | H15: 手动输入 | J15: 股东资本 | K15: ='5年财报'!K15 -> 50
B16: 财务收入/支出 | C16: ='6年经营'!C60 -> 0 | F16: 成品 | H16: 手动输入 | J16: 利润留存 | K16: ='5年财报'!K16+'5年财报'!K17 -> 19
B17: 额外收入/支出 | C17: ='6年经营'!C61 -> 0 | F17: 材料 | H17: 手动输入 | J17: 年度净利润 | K17: =C22 -> 0
F18: 所得税后现金 | G18: =G13-C21 -> 35
B19: 税前利润 | C19: =C13-C16+C17 -> 0 | F19: 总流动资产 | G19: =SUM(G14:G18) -> 35 | J19: 总股东权益 | K19: =K15+K16+K17 -> 69
B21: 所得税 | C21: =IF((FIXED(C19*C24,0)-0)<0,0,FIXED(C19*C24,0,TRUE)) -> 0
B22: 年度净利润 | C22: =C19-C21 -> 0 | F22: 总资产 | G22: =G9+G19 -> 78 | J22: 总负债权益 | K22: =K19+K10 -> 89
B24: 一般企业0.25 | D24: 手工输入
B25: 高新企业0.15
B26: 全额弥补亏损0

Sheet 7年经营
A1: 年 初 工 作 | B1: 1.支付上年度所得税 | E1: 一般企业25%，高新企业15% 从现金取出放到利息中 | M1: ='6年财报'!C21 -> 0 | O1: 综合费用
B2: 2.召开年度经营会议 | E2: 调整公司战略，制定当年经营和工作计划 | K2: 计划收入 | O2: =P5+O21+O22+O29+O33+O34+O40+O45+O48+O53 -> 0
B3: 3.市场竞标 | D3: 区域 | E3: 基础产品 | G3: 标准产品 | I3: 精密产品 | K3: 智能产品 | M3: 区域市场 订单总价 | O3: 订单 总额 | P3: 市场 投入
E4: 总价 | G4: 总价 | I4: 总价 | K4: 总价
D5: 本地 | M5: =SUM(E5:L5) -> 0 | O5: =SUM(M5:N8) -> 0
D6: 区域 | M6: =SUM(E6:L6) -> 0
D7: 全国 | M7: =SUM(E7:L7) -> 0
D8: 全球 | M8: =SUM(E8:L8) -> 0
A9: 每季工作 | B9: 1.短期贷款更新账期 年利率：10% | G9: 第一季度 | H9: 二季度 | I9: 第二季度 | J9: 四季度 | K9: 第三季度 | M9: 第四季度 | O9: 总计 | P9: 增减
E10: 到期还贷 | O10: =SUM(G10:N10) -> 0 | P10: ='6年财报'!K7+O12-O10 -> 20
E11: 付利息 | O11: =SUM(G11:N11) -> 0
E12: 新增贷款 | O12: =SUM(G12:N12) -> 0
A13: 每季 度 工 作 | B13: 2.支付材料费用 支付前一季度订购的产品材料费，并将订单移至产品库 | G13: 第一季度 | H13: 二季度 | I13: 第二季度 | J13: 四季度 | K13: 第三季度 | M13: 第四季度 | O13: 总计
E14: 基础产品 | O14: =G14+I14+K14+M14 -> 0
E15: 标准产品 | O15: =G15+I15+K15+M15 -> 0
E16: 精密产品 | O16: =G16+I16+K16+M16 -> 0
E17: 智能产品 | O17: =G17+I17+K17+M17 -> 0
E18: 合计 | G18: =G14+G15+G16+G17 -> 0 | H18: =SUM(H14:H17) -> 0 | I18: =I14+I15+I16+I17 -> 0 | K18: =K14+K15+K16+K17 -> 0 | M18: =M14+M15+M16+M17 -> 0 | O18: =G18+I18+K18+M18 -> 0
A19: 每季 度 工 作 | B19: 3.产品进度更新 （每个在建交付产品向前移动一格，满格的移动到产品交付库）
B20: 4.生产线调整 变更产品 拆除变卖 新生产线投资安装 | G20: 第一季度 | H20: 二季度 | I20: 第二季度 | J20: 四季度 | K20: 第三季度 | M20: 第四季度 | O20: 总计
E21: 变更产品 | O21: =SUM(G21:N21) -> 0
E22: 生产线拆除 1M/条 | O22: =G22+I22+K22+M22 -> 0
E23: 生产线出售 从资产残值中取出相应金额到现金并记账 | O23: =SUM(G23:N25) -> 0
E26: 新生产线安装 | O26: =SUM(G26:N26) -> 0
E27: 建成生产线转固 | F27: 生产线残值 | O27: =SUM(G27:N27) -> 0
F28: 待折资产 | O28: =SUM(G28:N28) -> 0
B29: 5.人力资源管理 招聘/辞退/待岗/上岗/培训 | E29: 支付招聘、辞退、培训、待岗费用 | O29: =SUM(G29:N30) -> 0
B31: 6.生产线空位投放材料，发放工人工资 | E31: 支付交付产品的生产线使用人员工资 | O31: =SUM(G31:N32) -> 0
B33: 7.新技术研发投入 | E33: 技术研发 | O33: =SUM(G33:N33) -> 0
B34: 8.管理体系投入 | E34: 质量环境健康费用 | O34: =SUM(G34:N34) -> 0
B35: 9.下新供应链订单，以空桶代替，放到供应链订单上
B36: 10.更新应收账款，所有应收向左移动一格 | E36: 如应收账款进入现金区做记录 | O36: =SUM(G36:N37) -> 0
B38: 11.产品验收交付 | E38: 交货订单销售额 | O38: =SUM(G38:N38) -> 0
E39: 交货订单成本 | O39: =SUM(G39:N39) -> 0
B40: 12.支付管理人员费用 | E40: 每季1M | O40: =SUM(G40:N40) -> 0
O41: 总计 | P41: 增减
A42: 年末工作 | B42: 1.办理长期贷款 账期更新 | E42: 付利息 | G42: 年利率5% | P42: ='6年财报'!K8+O44-O43 -> 0
E43: 到期还款 | G43: ------------------------------------------------------
E44: 办理新贷款 | G44: ------------------------------------------------------
B45: 2.支付生产线年度维护费 1M/条 | G45: ------------------------------------------------------
...

Sheet 7年财报
B2: 损益表 | F2: 资产负债表
F3: 资产 | J3: 负 债 ＋ 权 益
B4: 销售收入 | C4: ='7年经营'!O38 -> 0 | F4: 非流动资产 | J4: 负债
B5: 直接成本 | C5: ='7年经营'!O39 -> 0 | F5: 在建生产线 | G5: ='7年经营'!O52 -> 0
F6: 厂房 | G6: ='6年财报'!G6+'7年经营'!E60 -> 40
B7: 毛利 | C7: =C4-C5 -> 0 | F7: 生产线残值 | G7: ='6年财报'!G7+'7年经营'!E61 -> 3 | J7: 短期负债 | K7: ='7年经营'!P10 -> 20
F8: 待折资产 | G8: ='6年财报'!G8+'7年经营'!G61 -> 0 | J8: 长期负债 | K8: ='7年经营'!P42 -> 0
F9: 总非流动资产 | G9: =G5+G6+G7+G8 -> 43
B10: 综合费用 | C10: ='7年经营'!O2 -> 0 | J10: 总负债 | K10: =K6+K7+K8 -> 20
B11: 折旧 | C11: ='7年经营'!O51 -> 0 | F11: 流动资产
B13: 营业利润 | C13: =C7-C10-C11 -> 0 | F13: 现金 | G13: ='7年经营'!C59 -> 35 | J13: 总权益
F14: 应收款 | G14: ='6年财报'!G14+'7年经营'!O38-'7年经营'!O36 -> 0
F15: 在制品 | H15: 手动输入 | J15: 股东资本 | K15: ='6年财报'!K15 -> 50
B16: 财务收入/支出 | C16: ='7年经营'!C60 -> 0 | F16: 成品 | H16: 手动输入 | J16: 利润留存 | K16: ='6年财报'!K16+'6年财报'!K17 -> 19
B17: 额外收入/支出 | C17: ='7年经营'!C61 -> 0 | F17: 材料 | H17: 手动输入 | J17: 年度净利润 | K17: =C22 -> 0
F18: 所得税后现金 | G18: =G13-C21 -> 35
B19: 税前利润 | C19: =C13-C16+C17 -> 0 | F19: 总流动资产 | G19: =SUM(G14:G18) -> 35 | J19: 总股东权益 | K19: =K15+K16+K17 -> 69
B21: 所得税 | C21: =IF((FIXED(C19*C24,0)-0)<0,0,FIXED(C19*C24,0,TRUE)) -> 0
B22: 年度净利润 | C22: =C19-C21 -> 0 | F22: 总资产 | G22: =G9+G19 -> 78 | J22: 总负债权益 | K22: =K19+K10 -> 89
B24: 一般企业0.25 | D24: 手工输入
B25: 高新企业0.15
B26: 全额弥补亏损0

Sheet 8年经营
A1: 年 初 工 作 | B1: 1.支付上年度所得税 | E1: 一般企业25%，高新企业15% 从现金取出放到利息中 | M1: ='7年财报'!C21 -> 0 | O1: 综合费用
B2: 2.召开年度经营会议 | E2: 调整公司战略，制定当年经营和工作计划 | K2: 计划收入 | O2: =P5+O21+O22+O29+O33+O34+O40+O45+O48+O53 -> 0
B3: 3.市场竞标 | D3: 区域 | E3: 基础产品 | G3: 标准产品 | I3: 精密产品 | K3: 智能产品 | M3: 区域市场 订单总价 | O3: 订单 总额 | P3: 市场 投入
E4: 总价 | G4: 总价 | I4: 总价 | K4: 总价
D5: 本地 | M5: =SUM(E5:L5) -> 0 | O5: =SUM(M5:N8) -> 0
D6: 区域 | M6: =SUM(E6:L6) -> 0
D7: 全国 | M7: =SUM(E7:L7) -> 0
D8: 全球 | M8: =SUM(E8:L8) -> 0
A9: 每季工作 | B9: 1.短期贷款更新账期 年利率：10% | G9: 第一季度 | H9: 二季度 | I9: 第二季度 | J9: 四季度 | K9: 第三季度 | M9: 第四季度 | O9: 总计 | P9: 增减
E10: 到期还贷 | O10: =SUM(G10:N10) -> 0 | P10: ='7年财报'!K7+O12-O10 -> 20
E11: 付利息 | O11: =SUM(G11:N11) -> 0
E12: 新增贷款 | O12: =SUM(G12:N12) -> 0
A13: 每季 度 工 作 | B13: 2.支付材料费用 支付前一季度订购的产品材料费，并将订单移至产品库 | G13: 第一季度 | H13: 二季度 | I13: 第二季度 | J13: 四季度 | K13: 第三季度 | M13: 第四季度 | O13: 总计
E14: 基础产品 | O14: =G14+I14+K14+M14 -> 0
E15: 标准产品 | O15: =G15+I15+K15+M15 -> 0
E16: 精密产品 | O16: =G16+I16+K16+M16 -> 0
E17: 智能产品 | O17: =G17+I17+K17+M17 -> 0
E18: 合计 | G18: =G14+G15+G16+G17 -> 0 | H18: =SUM(H14:H17) -> 0 | I18: =I14+I15+I16+I17 -> 0 | K18: =K14+K15+K16+K17 -> 0 | M18: =M14+M15+M16+M17 -> 0 | O18: =G18+I18+K18+M18 -> 0
A19: 每季 度 工 作 | B19: 3.产品进度更新 （每个在建交付产品向前移动一格，满格的移动到产品交付库）
B20: 4.生产线调整 变更产品 拆除变卖 新生产线投资安装 | G20: 第一季度 | H20: 二季度 | I20: 第二季度 | J20: 四季度 | K20: 第三季度 | M20: 第四季度 | O20: 总计
E21: 变更产品 | O21: =SUM(G21:N21) -> 0
E22: 生产线拆除 1M/条 | O22: =G22+I22+K22+M22 -> 0
E23: 生产线出售 从资产残值中取出相应金额到现金并记账 | O23: =SUM(G23:N25) -> 0
E26: 新生产线安装 | O26: =SUM(G26:N26) -> 0
E27: 建成生产线转固 | F27: 生产线残值 | O27: =SUM(G27:N27) -> 0
F28: 待折资产 | O28: =SUM(G28:N28) -> 0
B29: 5.人力资源管理 招聘/辞退/待岗/上岗/培训 | E29: 支付招聘、辞退、培训、待岗费用 | O29: =SUM(G29:N30) -> 0
B31: 6.生产线空位投放材料，发放工人工资 | E31: 支付交付产品的生产线使用人员工资 | O31: =SUM(G31:N32) -> 0
B33: 7.新技术研发投入 | E33: 技术研发 | O33: =SUM(G33:N33) -> 0
B34: 8.管理体系投入 | E34: 质量环境健康费用 | O34: =SUM(G34:N34) -> 0
B35: 9.下新供应链订单，以空桶代替，放到供应链订单上
B36: 10.更新应收账款，所有应收向左移动一格 | E36: 如应收账款进入现金区做记录 | O36: =SUM(G36:N37) -> 0
B38: 11.产品验收交付 | E38: 交货订单销售额 | O38: =SUM(G38:N38) -> 0
E39: 交货订单成本 | O39: =SUM(G39:N39) -> 0
B40: 12.支付管理人员费用 | E40: 每季1M | O40: =SUM(G40:N40) -> 0
O41: 总计 | P41: 增减
A42: 年末工作 | B42: 1.办理长期贷款 账期更新 | E42: 付利息 | G42: 年利率5% | P42: ='7年财报'!K8+O44-O43 -> 0
E43: 到期还款 | G43: ------------------------------------------------------
E44: 办理新贷款 | G44: ------------------------------------------------------
B45: 2.支付生产线年度维护费 1M/条 | G45: ------------------------------------------------------
...

Sheet 8年财报
B2: 损益表 | F2: 资产负债表
F3: 资产 | J3: 负 债 ＋ 权 益
B4: 销售收入 | C4: ='8年经营'!O38 -> 0 | F4: 非流动资产 | J4: 负债
B5: 直接成本 | C5: ='8年经营'!O39 -> 0 | F5: 在建生产线 | G5: ='8年经营'!O52 -> 0
F6: 厂房 | G6: ='7年财报'!G6+'8年经营'!E60 -> 40
B7: 毛利 | C7: =C4-C5 -> 0 | F7: 生产线残值 | G7: ='7年财报'!G7+'8年经营'!E61 -> 3 | J7: 短期负债 | K7: ='8年经营'!P10 -> 20
F8: 待折资产 | G8: ='7年财报'!G8+'8年经营'!G61 -> 0 | J8: 长期负债 | K8: ='8年经营'!P42 -> 0
F9: 总非流动资产 | G9: =G5+G6+G7+G8 -> 43
B10: 综合费用 | C10: ='8年经营'!O2 -> 0 | J10: 总负债 | K10: =K6+K7+K8 -> 20
B11: 折旧 | C11: ='8年经营'!O51 -> 0 | F11: 流动资产
B13: 营业利润 | C13: =C7-C10-C11 -> 0 | F13: 现金 | G13: ='8年经营'!C59 -> 35 | J13: 总权益
F14: 应收款 | G14: ='7年财报'!G14+'8年经营'!O38-'8年经营'!O36 -> 0
F15: 在制品 | H15: 手动输入 | J15: 股东资本 | K15: ='7年财报'!K15 -> 50
B16: 财务收入/支出 | C16: ='8年经营'!C60 -> 0 | F16: 成品 | H16: 手动输入 | J16: 利润留存 | K16: ='7年财报'!K16+'7年财报'!K17 -> 19
B17: 额外收入/支出 | C17: ='8年经营'!C61 -> 0 | F17: 材料 | H17: 手动输入 | J17: 年度净利润 | K17: =C22 -> 0
F18: 所得税后现金 | G18: =G13-C21 -> 35
B19: 税前利润 | C19: =C13-C16+C17 -> 0 | F19: 总流动资产 | G19: =SUM(G14:G18) -> 35 | J19: 总股东权益 | K19: =K15+K16+K17 -> 69
B21: 所得税 | C21: =IF((FIXED(C19*C24,0)-0)<0,0,FIXED(C19*C24,0,TRUE)) -> 0
B22: 年度净利润 | C22: =C19-C21 -> 0 | F22: 总资产 | G22: =G9+G19 -> 78 | J22: 总负债权益 | K22: =K19+K10 -> 89
B24: 一般企业0.25 | D24: 手工输入
B25: 高新企业0.15
B26: 全额弥补亏损0
